DEBUG:Chroma:Logger created
DEBUG:Chroma:Index not found
DEBUG:Chroma:Index saved to {self._save_folder}/index.bin
DEBUG:Chroma:Index saved to {self._save_folder}/index.bin
DEBUG:Chroma:time to pre process our knn query: 3.0994415283203125e-06
ERROR:__main__:Exception in handle_message:
Traceback (most recent call last):
  File "/Users/canberkvarli/Development/peacy/bot.py", line 66, in handle_message
    memory_context = retrieve_memory(user_message, n_results=3)
  File "/Users/canberkvarli/Development/peacy/memory_manager.py", line 46, in retrieve_memory
    results = collection.query(
  File "/Users/canberkvarli/Development/peacy/venv/lib/python3.10/site-packages/chromadb/api/models/Collection.py", line 165, in query
    return self._client._query(
  File "/Users/canberkvarli/Development/peacy/venv/lib/python3.10/site-packages/chromadb/api/local.py", line 192, in _query
    uuids, distances = self._db.get_nearest_neighbors(
  File "/Users/canberkvarli/Development/peacy/venv/lib/python3.10/site-packages/chromadb/db/clickhouse.py", line 393, in get_nearest_neighbors
    uuids, distances = self._idx.get_nearest_neighbors(
  File "/Users/canberkvarli/Development/peacy/venv/lib/python3.10/site-packages/chromadb/db/index/hnswlib.py", line 182, in get_nearest_neighbors
    database_ids, distances = self._index.knn_query(query, k=k, filter=filter_function)
RuntimeError: Cannot return the results in a contiguous 2D array. Probably ef or M is too small
DEBUG:Chroma:time to pre process our knn query: 4.0531158447265625e-06
ERROR:__main__:Exception in handle_message:
Traceback (most recent call last):
  File "/Users/canberkvarli/Development/peacy/bot.py", line 66, in handle_message
    memory_context = retrieve_memory(user_message, n_results=3)
  File "/Users/canberkvarli/Development/peacy/memory_manager.py", line 46, in retrieve_memory
    results = collection.query(
  File "/Users/canberkvarli/Development/peacy/venv/lib/python3.10/site-packages/chromadb/api/models/Collection.py", line 165, in query
    return self._client._query(
  File "/Users/canberkvarli/Development/peacy/venv/lib/python3.10/site-packages/chromadb/api/local.py", line 192, in _query
    uuids, distances = self._db.get_nearest_neighbors(
  File "/Users/canberkvarli/Development/peacy/venv/lib/python3.10/site-packages/chromadb/db/clickhouse.py", line 393, in get_nearest_neighbors
    uuids, distances = self._idx.get_nearest_neighbors(
  File "/Users/canberkvarli/Development/peacy/venv/lib/python3.10/site-packages/chromadb/db/index/hnswlib.py", line 182, in get_nearest_neighbors
    database_ids, distances = self._index.knn_query(query, k=k, filter=filter_function)
RuntimeError: Cannot return the results in a contiguous 2D array. Probably ef or M is too small
DEBUG:Chroma:time to pre process our knn query: 9.5367431640625e-07
ERROR:__main__:Exception in handle_message:
Traceback (most recent call last):
  File "/Users/canberkvarli/Development/peacy/bot.py", line 66, in handle_message
    memory_context = retrieve_memory(user_message, n_results=3)
  File "/Users/canberkvarli/Development/peacy/memory_manager.py", line 46, in retrieve_memory
    results = collection.query(
  File "/Users/canberkvarli/Development/peacy/venv/lib/python3.10/site-packages/chromadb/api/models/Collection.py", line 165, in query
    return self._client._query(
  File "/Users/canberkvarli/Development/peacy/venv/lib/python3.10/site-packages/chromadb/api/local.py", line 192, in _query
    uuids, distances = self._db.get_nearest_neighbors(
  File "/Users/canberkvarli/Development/peacy/venv/lib/python3.10/site-packages/chromadb/db/clickhouse.py", line 393, in get_nearest_neighbors
    uuids, distances = self._idx.get_nearest_neighbors(
  File "/Users/canberkvarli/Development/peacy/venv/lib/python3.10/site-packages/chromadb/db/index/hnswlib.py", line 182, in get_nearest_neighbors
    database_ids, distances = self._index.knn_query(query, k=k, filter=filter_function)
RuntimeError: Cannot return the results in a contiguous 2D array. Probably ef or M is too small
DEBUG:Chroma:time to pre process our knn query: 3.0994415283203125e-06
ERROR:__main__:Exception in handle_message:
Traceback (most recent call last):
  File "/Users/canberkvarli/Development/peacy/bot.py", line 66, in handle_message
    memory_context = retrieve_memory(user_message, n_results=3)
  File "/Users/canberkvarli/Development/peacy/memory_manager.py", line 46, in retrieve_memory
    results = collection.query(
  File "/Users/canberkvarli/Development/peacy/venv/lib/python3.10/site-packages/chromadb/api/models/Collection.py", line 165, in query
    return self._client._query(
  File "/Users/canberkvarli/Development/peacy/venv/lib/python3.10/site-packages/chromadb/api/local.py", line 192, in _query
    uuids, distances = self._db.get_nearest_neighbors(
  File "/Users/canberkvarli/Development/peacy/venv/lib/python3.10/site-packages/chromadb/db/clickhouse.py", line 393, in get_nearest_neighbors
    uuids, distances = self._idx.get_nearest_neighbors(
  File "/Users/canberkvarli/Development/peacy/venv/lib/python3.10/site-packages/chromadb/db/index/hnswlib.py", line 182, in get_nearest_neighbors
    database_ids, distances = self._index.knn_query(query, k=k, filter=filter_function)
RuntimeError: Cannot return the results in a contiguous 2D array. Probably ef or M is too small
DEBUG:Chroma:time to pre process our knn query: 1.9073486328125e-06
ERROR:__main__:Exception in handle_message:
Traceback (most recent call last):
  File "/Users/canberkvarli/Development/peacy/bot.py", line 66, in handle_message
    memory_context = retrieve_memory(user_message, n_results=3)
  File "/Users/canberkvarli/Development/peacy/memory_manager.py", line 46, in retrieve_memory
    results = collection.query(
  File "/Users/canberkvarli/Development/peacy/venv/lib/python3.10/site-packages/chromadb/api/models/Collection.py", line 165, in query
    return self._client._query(
  File "/Users/canberkvarli/Development/peacy/venv/lib/python3.10/site-packages/chromadb/api/local.py", line 192, in _query
    uuids, distances = self._db.get_nearest_neighbors(
  File "/Users/canberkvarli/Development/peacy/venv/lib/python3.10/site-packages/chromadb/db/clickhouse.py", line 393, in get_nearest_neighbors
    uuids, distances = self._idx.get_nearest_neighbors(
  File "/Users/canberkvarli/Development/peacy/venv/lib/python3.10/site-packages/chromadb/db/index/hnswlib.py", line 182, in get_nearest_neighbors
    database_ids, distances = self._index.knn_query(query, k=k, filter=filter_function)
RuntimeError: Cannot return the results in a contiguous 2D array. Probably ef or M is too small
DEBUG:Chroma:time to pre process our knn query: 1.1920928955078125e-06
ERROR:__main__:Exception in handle_message:
Traceback (most recent call last):
  File "/Users/canberkvarli/Development/peacy/bot.py", line 66, in handle_message
    memory_context = retrieve_memory(user_message, n_results=3)
  File "/Users/canberkvarli/Development/peacy/memory_manager.py", line 46, in retrieve_memory
    results = collection.query(
  File "/Users/canberkvarli/Development/peacy/venv/lib/python3.10/site-packages/chromadb/api/models/Collection.py", line 165, in query
    return self._client._query(
  File "/Users/canberkvarli/Development/peacy/venv/lib/python3.10/site-packages/chromadb/api/local.py", line 192, in _query
    uuids, distances = self._db.get_nearest_neighbors(
  File "/Users/canberkvarli/Development/peacy/venv/lib/python3.10/site-packages/chromadb/db/clickhouse.py", line 393, in get_nearest_neighbors
    uuids, distances = self._idx.get_nearest_neighbors(
  File "/Users/canberkvarli/Development/peacy/venv/lib/python3.10/site-packages/chromadb/db/index/hnswlib.py", line 182, in get_nearest_neighbors
    database_ids, distances = self._index.knn_query(query, k=k, filter=filter_function)
RuntimeError: Cannot return the results in a contiguous 2D array. Probably ef or M is too small
ERROR:__main__:Exception in update:
Traceback (most recent call last):
  File "/Users/canberkvarli/Development/peacy/venv/lib/python3.10/site-packages/telegram/vendor/ptb_urllib3/urllib3/connectionpool.py", line 614, in urlopen
    httplib_response = self._make_request(conn, method, url,
  File "/Users/canberkvarli/Development/peacy/venv/lib/python3.10/site-packages/telegram/vendor/ptb_urllib3/urllib3/connectionpool.py", line 402, in _make_request
    six.raise_from(e, None)
  File "<string>", line 2, in raise_from
  File "/Users/canberkvarli/Development/peacy/venv/lib/python3.10/site-packages/telegram/vendor/ptb_urllib3/urllib3/connectionpool.py", line 398, in _make_request
    httplib_response = conn.getresponse()
  File "/Users/canberkvarli/.pyenv/versions/3.10.4/lib/python3.10/http/client.py", line 1374, in getresponse
    response.begin()
  File "/Users/canberkvarli/.pyenv/versions/3.10.4/lib/python3.10/http/client.py", line 318, in begin
    version, status, reason = self._read_status()
  File "/Users/canberkvarli/.pyenv/versions/3.10.4/lib/python3.10/http/client.py", line 287, in _read_status
    raise RemoteDisconnected("Remote end closed connection without"
http.client.RemoteDisconnected: Remote end closed connection without response

During handling of the above exception, another exception occurred:

Traceback (most recent call last):
  File "/Users/canberkvarli/Development/peacy/venv/lib/python3.10/site-packages/telegram/utils/request.py", line 259, in _request_wrapper
    resp = self._con_pool.request(*args, **kwargs)
  File "/Users/canberkvarli/Development/peacy/venv/lib/python3.10/site-packages/telegram/vendor/ptb_urllib3/urllib3/request.py", line 68, in request
    return self.request_encode_body(method, url, fields=fields,
  File "/Users/canberkvarli/Development/peacy/venv/lib/python3.10/site-packages/telegram/vendor/ptb_urllib3/urllib3/request.py", line 148, in request_encode_body
    return self.urlopen(method, url, **extra_kw)
  File "/Users/canberkvarli/Development/peacy/venv/lib/python3.10/site-packages/telegram/vendor/ptb_urllib3/urllib3/poolmanager.py", line 244, in urlopen
    response = conn.urlopen(method, u.request_uri, **kw)
  File "/Users/canberkvarli/Development/peacy/venv/lib/python3.10/site-packages/telegram/vendor/ptb_urllib3/urllib3/connectionpool.py", line 665, in urlopen
    retries = retries.increment(method, url, error=e, _pool=self,
  File "/Users/canberkvarli/Development/peacy/venv/lib/python3.10/site-packages/telegram/vendor/ptb_urllib3/urllib3/util/retry.py", line 347, in increment
    raise six.reraise(type(error), error, _stacktrace)
  File "/Users/canberkvarli/Development/peacy/venv/lib/python3.10/site-packages/telegram/vendor/ptb_urllib3/urllib3/packages/six.py", line 685, in reraise
    raise value.with_traceback(tb)
  File "/Users/canberkvarli/Development/peacy/venv/lib/python3.10/site-packages/telegram/vendor/ptb_urllib3/urllib3/connectionpool.py", line 614, in urlopen
    httplib_response = self._make_request(conn, method, url,
  File "/Users/canberkvarli/Development/peacy/venv/lib/python3.10/site-packages/telegram/vendor/ptb_urllib3/urllib3/connectionpool.py", line 402, in _make_request
    six.raise_from(e, None)
  File "<string>", line 2, in raise_from
  File "/Users/canberkvarli/Development/peacy/venv/lib/python3.10/site-packages/telegram/vendor/ptb_urllib3/urllib3/connectionpool.py", line 398, in _make_request
    httplib_response = conn.getresponse()
  File "/Users/canberkvarli/.pyenv/versions/3.10.4/lib/python3.10/http/client.py", line 1374, in getresponse
    response.begin()
  File "/Users/canberkvarli/.pyenv/versions/3.10.4/lib/python3.10/http/client.py", line 318, in begin
    version, status, reason = self._read_status()
  File "/Users/canberkvarli/.pyenv/versions/3.10.4/lib/python3.10/http/client.py", line 287, in _read_status
    raise RemoteDisconnected("Remote end closed connection without"
telegram.vendor.ptb_urllib3.urllib3.exceptions.ProtocolError: ('Connection aborted.', RemoteDisconnected('Remote end closed connection without response'))

The above exception was the direct cause of the following exception:

Traceback (most recent call last):
  File "/Users/canberkvarli/Development/peacy/venv/lib/python3.10/site-packages/telegram/ext/dispatcher.py", line 557, in process_update
    handler.handle_update(update, self, check, context)
  File "/Users/canberkvarli/Development/peacy/venv/lib/python3.10/site-packages/telegram/ext/handler.py", line 199, in handle_update
    return self.callback(update, context)
  File "/Users/canberkvarli/Development/peacy/bot.py", line 53, in start_command
    update.message.reply_text("Hello! I am Peacy, your friendly AI mediator.")
  File "/Users/canberkvarli/Development/peacy/venv/lib/python3.10/site-packages/telegram/message.py", line 977, in reply_text
    return self.bot.send_message(
  File "/Users/canberkvarli/Development/peacy/venv/lib/python3.10/site-packages/telegram/bot.py", line 134, in decorator
    result = func(*args, **kwargs)
  File "/Users/canberkvarli/Development/peacy/venv/lib/python3.10/site-packages/telegram/bot.py", line 534, in send_message
    return self._message(  # type: ignore[return-value]
  File "/Users/canberkvarli/Development/peacy/venv/lib/python3.10/site-packages/telegram/ext/extbot.py", line 203, in _message
    result = super()._message(
  File "/Users/canberkvarli/Development/peacy/venv/lib/python3.10/site-packages/telegram/bot.py", line 344, in _message
    result = self._post(endpoint, data, timeout=timeout, api_kwargs=api_kwargs)
  File "/Users/canberkvarli/Development/peacy/venv/lib/python3.10/site-packages/telegram/bot.py", line 299, in _post
    return self.request.post(
  File "/Users/canberkvarli/Development/peacy/venv/lib/python3.10/site-packages/telegram/utils/request.py", line 361, in post
    result = self._request_wrapper(
  File "/Users/canberkvarli/Development/peacy/venv/lib/python3.10/site-packages/telegram/utils/request.py", line 265, in _request_wrapper
    raise NetworkError(f'urllib3 HTTPError {error}') from error
telegram.error.NetworkError: urllib3 HTTPError ('Connection aborted.', RemoteDisconnected('Remote end closed connection without response'))
DEBUG:Chroma:time to pre process our knn query: 2.1457672119140625e-06
ERROR:__main__:Exception in handle_message:
Traceback (most recent call last):
  File "/Users/canberkvarli/Development/peacy/bot.py", line 66, in handle_message
    memory_context = retrieve_memory(user_message, n_results=3)
  File "/Users/canberkvarli/Development/peacy/memory_manager.py", line 46, in retrieve_memory
    results = collection.query(
  File "/Users/canberkvarli/Development/peacy/venv/lib/python3.10/site-packages/chromadb/api/models/Collection.py", line 165, in query
    return self._client._query(
  File "/Users/canberkvarli/Development/peacy/venv/lib/python3.10/site-packages/chromadb/api/local.py", line 192, in _query
    uuids, distances = self._db.get_nearest_neighbors(
  File "/Users/canberkvarli/Development/peacy/venv/lib/python3.10/site-packages/chromadb/db/clickhouse.py", line 393, in get_nearest_neighbors
    uuids, distances = self._idx.get_nearest_neighbors(
  File "/Users/canberkvarli/Development/peacy/venv/lib/python3.10/site-packages/chromadb/db/index/hnswlib.py", line 182, in get_nearest_neighbors
    database_ids, distances = self._index.knn_query(query, k=k, filter=filter_function)
RuntimeError: Cannot return the results in a contiguous 2D array. Probably ef or M is too small
DEBUG:Chroma:time to pre process our knn query: 3.814697265625e-06
ERROR:__main__:Exception in handle_message:
Traceback (most recent call last):
  File "/Users/canberkvarli/Development/peacy/bot.py", line 66, in handle_message
    memory_context = retrieve_memory(user_message, n_results=3)
  File "/Users/canberkvarli/Development/peacy/memory_manager.py", line 46, in retrieve_memory
    results = collection.query(
  File "/Users/canberkvarli/Development/peacy/venv/lib/python3.10/site-packages/chromadb/api/models/Collection.py", line 165, in query
    return self._client._query(
  File "/Users/canberkvarli/Development/peacy/venv/lib/python3.10/site-packages/chromadb/api/local.py", line 192, in _query
    uuids, distances = self._db.get_nearest_neighbors(
  File "/Users/canberkvarli/Development/peacy/venv/lib/python3.10/site-packages/chromadb/db/clickhouse.py", line 393, in get_nearest_neighbors
    uuids, distances = self._idx.get_nearest_neighbors(
  File "/Users/canberkvarli/Development/peacy/venv/lib/python3.10/site-packages/chromadb/db/index/hnswlib.py", line 182, in get_nearest_neighbors
    database_ids, distances = self._index.knn_query(query, k=k, filter=filter_function)
RuntimeError: Cannot return the results in a contiguous 2D array. Probably ef or M is too small
DEBUG:Chroma:time to pre process our knn query: 1.9073486328125e-06
ERROR:__main__:Exception in handle_message:
Traceback (most recent call last):
  File "/Users/canberkvarli/Development/peacy/bot.py", line 66, in handle_message
    memory_context = retrieve_memory(user_message, n_results=3)
  File "/Users/canberkvarli/Development/peacy/memory_manager.py", line 46, in retrieve_memory
    results = collection.query(
  File "/Users/canberkvarli/Development/peacy/venv/lib/python3.10/site-packages/chromadb/api/models/Collection.py", line 165, in query
    return self._client._query(
  File "/Users/canberkvarli/Development/peacy/venv/lib/python3.10/site-packages/chromadb/api/local.py", line 192, in _query
    uuids, distances = self._db.get_nearest_neighbors(
  File "/Users/canberkvarli/Development/peacy/venv/lib/python3.10/site-packages/chromadb/db/clickhouse.py", line 393, in get_nearest_neighbors
    uuids, distances = self._idx.get_nearest_neighbors(
  File "/Users/canberkvarli/Development/peacy/venv/lib/python3.10/site-packages/chromadb/db/index/hnswlib.py", line 182, in get_nearest_neighbors
    database_ids, distances = self._index.knn_query(query, k=k, filter=filter_function)
RuntimeError: Cannot return the results in a contiguous 2D array. Probably ef or M is too small
WARNING:apscheduler.executors.default:Run time of job "summarize_conversations (trigger: interval[0:30:00], next run at: 2025-03-16 08:48:03 UTC)" was missed by 0:08:26.370876
ERROR:telegram.ext.updater:Error while getting Updates: urllib3 HTTPError ('Connection aborted.', RemoteDisconnected('Remote end closed connection without response'))
ERROR:__main__:Exception in update:
Traceback (most recent call last):
  File "/Users/canberkvarli/Development/peacy/venv/lib/python3.10/site-packages/telegram/vendor/ptb_urllib3/urllib3/connectionpool.py", line 614, in urlopen
    httplib_response = self._make_request(conn, method, url,
  File "/Users/canberkvarli/Development/peacy/venv/lib/python3.10/site-packages/telegram/vendor/ptb_urllib3/urllib3/connectionpool.py", line 402, in _make_request
    six.raise_from(e, None)
  File "<string>", line 2, in raise_from
  File "/Users/canberkvarli/Development/peacy/venv/lib/python3.10/site-packages/telegram/vendor/ptb_urllib3/urllib3/connectionpool.py", line 398, in _make_request
    httplib_response = conn.getresponse()
  File "/Users/canberkvarli/.pyenv/versions/3.10.4/lib/python3.10/http/client.py", line 1374, in getresponse
    response.begin()
  File "/Users/canberkvarli/.pyenv/versions/3.10.4/lib/python3.10/http/client.py", line 318, in begin
    version, status, reason = self._read_status()
  File "/Users/canberkvarli/.pyenv/versions/3.10.4/lib/python3.10/http/client.py", line 287, in _read_status
    raise RemoteDisconnected("Remote end closed connection without"
http.client.RemoteDisconnected: Remote end closed connection without response

During handling of the above exception, another exception occurred:

Traceback (most recent call last):
  File "/Users/canberkvarli/Development/peacy/venv/lib/python3.10/site-packages/telegram/utils/request.py", line 259, in _request_wrapper
    resp = self._con_pool.request(*args, **kwargs)
  File "/Users/canberkvarli/Development/peacy/venv/lib/python3.10/site-packages/telegram/vendor/ptb_urllib3/urllib3/request.py", line 68, in request
    return self.request_encode_body(method, url, fields=fields,
  File "/Users/canberkvarli/Development/peacy/venv/lib/python3.10/site-packages/telegram/vendor/ptb_urllib3/urllib3/request.py", line 148, in request_encode_body
    return self.urlopen(method, url, **extra_kw)
  File "/Users/canberkvarli/Development/peacy/venv/lib/python3.10/site-packages/telegram/vendor/ptb_urllib3/urllib3/poolmanager.py", line 244, in urlopen
    response = conn.urlopen(method, u.request_uri, **kw)
  File "/Users/canberkvarli/Development/peacy/venv/lib/python3.10/site-packages/telegram/vendor/ptb_urllib3/urllib3/connectionpool.py", line 665, in urlopen
    retries = retries.increment(method, url, error=e, _pool=self,
  File "/Users/canberkvarli/Development/peacy/venv/lib/python3.10/site-packages/telegram/vendor/ptb_urllib3/urllib3/util/retry.py", line 347, in increment
    raise six.reraise(type(error), error, _stacktrace)
  File "/Users/canberkvarli/Development/peacy/venv/lib/python3.10/site-packages/telegram/vendor/ptb_urllib3/urllib3/packages/six.py", line 685, in reraise
    raise value.with_traceback(tb)
  File "/Users/canberkvarli/Development/peacy/venv/lib/python3.10/site-packages/telegram/vendor/ptb_urllib3/urllib3/connectionpool.py", line 614, in urlopen
    httplib_response = self._make_request(conn, method, url,
  File "/Users/canberkvarli/Development/peacy/venv/lib/python3.10/site-packages/telegram/vendor/ptb_urllib3/urllib3/connectionpool.py", line 402, in _make_request
    six.raise_from(e, None)
  File "<string>", line 2, in raise_from
  File "/Users/canberkvarli/Development/peacy/venv/lib/python3.10/site-packages/telegram/vendor/ptb_urllib3/urllib3/connectionpool.py", line 398, in _make_request
    httplib_response = conn.getresponse()
  File "/Users/canberkvarli/.pyenv/versions/3.10.4/lib/python3.10/http/client.py", line 1374, in getresponse
    response.begin()
  File "/Users/canberkvarli/.pyenv/versions/3.10.4/lib/python3.10/http/client.py", line 318, in begin
    version, status, reason = self._read_status()
  File "/Users/canberkvarli/.pyenv/versions/3.10.4/lib/python3.10/http/client.py", line 287, in _read_status
    raise RemoteDisconnected("Remote end closed connection without"
telegram.vendor.ptb_urllib3.urllib3.exceptions.ProtocolError: ('Connection aborted.', RemoteDisconnected('Remote end closed connection without response'))

The above exception was the direct cause of the following exception:

Traceback (most recent call last):
  File "/Users/canberkvarli/Development/peacy/venv/lib/python3.10/site-packages/telegram/ext/updater.py", line 651, in _network_loop_retry
    if not action_cb():
  File "/Users/canberkvarli/Development/peacy/venv/lib/python3.10/site-packages/telegram/ext/updater.py", line 602, in polling_action_cb
    updates = self.bot.get_updates(
  File "/Users/canberkvarli/Development/peacy/venv/lib/python3.10/site-packages/telegram/ext/extbot.py", line 228, in get_updates
    updates = super().get_updates(
  File "/Users/canberkvarli/Development/peacy/venv/lib/python3.10/site-packages/telegram/bot.py", line 134, in decorator
    result = func(*args, **kwargs)
  File "/Users/canberkvarli/Development/peacy/venv/lib/python3.10/site-packages/telegram/bot.py", line 3140, in get_updates
    self._post(
  File "/Users/canberkvarli/Development/peacy/venv/lib/python3.10/site-packages/telegram/bot.py", line 299, in _post
    return self.request.post(
  File "/Users/canberkvarli/Development/peacy/venv/lib/python3.10/site-packages/telegram/utils/request.py", line 361, in post
    result = self._request_wrapper(
  File "/Users/canberkvarli/Development/peacy/venv/lib/python3.10/site-packages/telegram/utils/request.py", line 265, in _request_wrapper
    raise NetworkError(f'urllib3 HTTPError {error}') from error
telegram.error.NetworkError: urllib3 HTTPError ('Connection aborted.', RemoteDisconnected('Remote end closed connection without response'))
ERROR:telegram.ext.updater:Error while getting Updates: urllib3 HTTPError ('Connection aborted.', ConnectionResetError(54, 'Connection reset by peer'))
ERROR:__main__:Exception in update:
Traceback (most recent call last):
  File "/Users/canberkvarli/Development/peacy/venv/lib/python3.10/site-packages/telegram/vendor/ptb_urllib3/urllib3/connectionpool.py", line 614, in urlopen
    httplib_response = self._make_request(conn, method, url,
  File "/Users/canberkvarli/Development/peacy/venv/lib/python3.10/site-packages/telegram/vendor/ptb_urllib3/urllib3/connectionpool.py", line 360, in _make_request
    self._validate_conn(conn)
  File "/Users/canberkvarli/Development/peacy/venv/lib/python3.10/site-packages/telegram/vendor/ptb_urllib3/urllib3/connectionpool.py", line 857, in _validate_conn
    super(HTTPSConnectionPool, self)._validate_conn(conn)
  File "/Users/canberkvarli/Development/peacy/venv/lib/python3.10/site-packages/telegram/vendor/ptb_urllib3/urllib3/connectionpool.py", line 289, in _validate_conn
    conn.connect()
  File "/Users/canberkvarli/Development/peacy/venv/lib/python3.10/site-packages/telegram/vendor/ptb_urllib3/urllib3/connection.py", line 319, in connect
    self.sock = ssl_wrap_socket(
  File "/Users/canberkvarli/Development/peacy/venv/lib/python3.10/site-packages/telegram/vendor/ptb_urllib3/urllib3/util/ssl_.py", line 324, in ssl_wrap_socket
    return context.wrap_socket(sock, server_hostname=server_hostname)
  File "/Users/canberkvarli/.pyenv/versions/3.10.4/lib/python3.10/ssl.py", line 512, in wrap_socket
    return self.sslsocket_class._create(
  File "/Users/canberkvarli/.pyenv/versions/3.10.4/lib/python3.10/ssl.py", line 1070, in _create
    self.do_handshake()
  File "/Users/canberkvarli/.pyenv/versions/3.10.4/lib/python3.10/ssl.py", line 1341, in do_handshake
    self._sslobj.do_handshake()
ConnectionResetError: [Errno 54] Connection reset by peer

During handling of the above exception, another exception occurred:

Traceback (most recent call last):
  File "/Users/canberkvarli/Development/peacy/venv/lib/python3.10/site-packages/telegram/utils/request.py", line 259, in _request_wrapper
    resp = self._con_pool.request(*args, **kwargs)
  File "/Users/canberkvarli/Development/peacy/venv/lib/python3.10/site-packages/telegram/vendor/ptb_urllib3/urllib3/request.py", line 68, in request
    return self.request_encode_body(method, url, fields=fields,
  File "/Users/canberkvarli/Development/peacy/venv/lib/python3.10/site-packages/telegram/vendor/ptb_urllib3/urllib3/request.py", line 148, in request_encode_body
    return self.urlopen(method, url, **extra_kw)
  File "/Users/canberkvarli/Development/peacy/venv/lib/python3.10/site-packages/telegram/vendor/ptb_urllib3/urllib3/poolmanager.py", line 244, in urlopen
    response = conn.urlopen(method, u.request_uri, **kw)
  File "/Users/canberkvarli/Development/peacy/venv/lib/python3.10/site-packages/telegram/vendor/ptb_urllib3/urllib3/connectionpool.py", line 665, in urlopen
    retries = retries.increment(method, url, error=e, _pool=self,
  File "/Users/canberkvarli/Development/peacy/venv/lib/python3.10/site-packages/telegram/vendor/ptb_urllib3/urllib3/util/retry.py", line 347, in increment
    raise six.reraise(type(error), error, _stacktrace)
  File "/Users/canberkvarli/Development/peacy/venv/lib/python3.10/site-packages/telegram/vendor/ptb_urllib3/urllib3/packages/six.py", line 685, in reraise
    raise value.with_traceback(tb)
  File "/Users/canberkvarli/Development/peacy/venv/lib/python3.10/site-packages/telegram/vendor/ptb_urllib3/urllib3/connectionpool.py", line 614, in urlopen
    httplib_response = self._make_request(conn, method, url,
  File "/Users/canberkvarli/Development/peacy/venv/lib/python3.10/site-packages/telegram/vendor/ptb_urllib3/urllib3/connectionpool.py", line 360, in _make_request
    self._validate_conn(conn)
  File "/Users/canberkvarli/Development/peacy/venv/lib/python3.10/site-packages/telegram/vendor/ptb_urllib3/urllib3/connectionpool.py", line 857, in _validate_conn
    super(HTTPSConnectionPool, self)._validate_conn(conn)
  File "/Users/canberkvarli/Development/peacy/venv/lib/python3.10/site-packages/telegram/vendor/ptb_urllib3/urllib3/connectionpool.py", line 289, in _validate_conn
    conn.connect()
  File "/Users/canberkvarli/Development/peacy/venv/lib/python3.10/site-packages/telegram/vendor/ptb_urllib3/urllib3/connection.py", line 319, in connect
    self.sock = ssl_wrap_socket(
  File "/Users/canberkvarli/Development/peacy/venv/lib/python3.10/site-packages/telegram/vendor/ptb_urllib3/urllib3/util/ssl_.py", line 324, in ssl_wrap_socket
    return context.wrap_socket(sock, server_hostname=server_hostname)
  File "/Users/canberkvarli/.pyenv/versions/3.10.4/lib/python3.10/ssl.py", line 512, in wrap_socket
    return self.sslsocket_class._create(
  File "/Users/canberkvarli/.pyenv/versions/3.10.4/lib/python3.10/ssl.py", line 1070, in _create
    self.do_handshake()
  File "/Users/canberkvarli/.pyenv/versions/3.10.4/lib/python3.10/ssl.py", line 1341, in do_handshake
    self._sslobj.do_handshake()
telegram.vendor.ptb_urllib3.urllib3.exceptions.ProtocolError: ('Connection aborted.', ConnectionResetError(54, 'Connection reset by peer'))

The above exception was the direct cause of the following exception:

Traceback (most recent call last):
  File "/Users/canberkvarli/Development/peacy/venv/lib/python3.10/site-packages/telegram/ext/updater.py", line 651, in _network_loop_retry
    if not action_cb():
  File "/Users/canberkvarli/Development/peacy/venv/lib/python3.10/site-packages/telegram/ext/updater.py", line 602, in polling_action_cb
    updates = self.bot.get_updates(
  File "/Users/canberkvarli/Development/peacy/venv/lib/python3.10/site-packages/telegram/ext/extbot.py", line 228, in get_updates
    updates = super().get_updates(
  File "/Users/canberkvarli/Development/peacy/venv/lib/python3.10/site-packages/telegram/bot.py", line 134, in decorator
    result = func(*args, **kwargs)
  File "/Users/canberkvarli/Development/peacy/venv/lib/python3.10/site-packages/telegram/bot.py", line 3140, in get_updates
    self._post(
  File "/Users/canberkvarli/Development/peacy/venv/lib/python3.10/site-packages/telegram/bot.py", line 299, in _post
    return self.request.post(
  File "/Users/canberkvarli/Development/peacy/venv/lib/python3.10/site-packages/telegram/utils/request.py", line 361, in post
    result = self._request_wrapper(
  File "/Users/canberkvarli/Development/peacy/venv/lib/python3.10/site-packages/telegram/utils/request.py", line 265, in _request_wrapper
    raise NetworkError(f'urllib3 HTTPError {error}') from error
telegram.error.NetworkError: urllib3 HTTPError ('Connection aborted.', ConnectionResetError(54, 'Connection reset by peer'))
WARNING:telegram.vendor.ptb_urllib3.urllib3.connectionpool:Retrying (Retry(total=2, connect=None, read=None, redirect=None)) after connection broken by 'ConnectTimeoutError(<telegram.vendor.ptb_urllib3.urllib3.connectionpool.HTTPSConnectionPool object at 0x16f907a60>, 'Connect timed out. (connect timeout=5.0)')': /bot7327305156:AAGFKRpEVb48nB1PtSaLsPYRH8D-W9IVXiw/getUpdates
WARNING:telegram.vendor.ptb_urllib3.urllib3.connectionpool:Retrying (Retry(total=2, connect=None, read=None, redirect=None)) after connection broken by 'ConnectTimeoutError(<telegram.vendor.ptb_urllib3.urllib3.connectionpool.HTTPSConnectionPool object at 0x16f907a60>, 'Connect timed out. (connect timeout=5.0)')': /bot7327305156:AAGFKRpEVb48nB1PtSaLsPYRH8D-W9IVXiw/getUpdates
WARNING:telegram.vendor.ptb_urllib3.urllib3.connectionpool:Retrying (Retry(total=2, connect=None, read=None, redirect=None)) after connection broken by 'NewConnectionError('<telegram.vendor.ptb_urllib3.urllib3.connection.VerifiedHTTPSConnection object at 0x16f921000>: Failed to establish a new connection: [Errno 8] nodename nor servname provided, or not known')': /bot7327305156:AAGFKRpEVb48nB1PtSaLsPYRH8D-W9IVXiw/getUpdates
WARNING:telegram.vendor.ptb_urllib3.urllib3.connectionpool:Retrying (Retry(total=1, connect=None, read=None, redirect=None)) after connection broken by 'NewConnectionError('<telegram.vendor.ptb_urllib3.urllib3.connection.VerifiedHTTPSConnection object at 0x16f922440>: Failed to establish a new connection: [Errno 8] nodename nor servname provided, or not known')': /bot7327305156:AAGFKRpEVb48nB1PtSaLsPYRH8D-W9IVXiw/getUpdates
WARNING:telegram.vendor.ptb_urllib3.urllib3.connectionpool:Retrying (Retry(total=0, connect=None, read=None, redirect=None)) after connection broken by 'NewConnectionError('<telegram.vendor.ptb_urllib3.urllib3.connection.VerifiedHTTPSConnection object at 0x16f921180>: Failed to establish a new connection: [Errno 8] nodename nor servname provided, or not known')': /bot7327305156:AAGFKRpEVb48nB1PtSaLsPYRH8D-W9IVXiw/getUpdates
ERROR:telegram.ext.updater:Error while getting Updates: urllib3 HTTPError HTTPSConnectionPool(host='api.telegram.org', port=443): Max retries exceeded with url: /bot7327305156:AAGFKRpEVb48nB1PtSaLsPYRH8D-W9IVXiw/getUpdates (Caused by NewConnectionError('<telegram.vendor.ptb_urllib3.urllib3.connection.VerifiedHTTPSConnection object at 0x16f921930>: Failed to establish a new connection: [Errno 8] nodename nor servname provided, or not known'))
ERROR:__main__:Exception in update:
Traceback (most recent call last):
  File "/Users/canberkvarli/Development/peacy/venv/lib/python3.10/site-packages/telegram/vendor/ptb_urllib3/urllib3/connection.py", line 140, in _new_conn
    conn = connection.create_connection(
  File "/Users/canberkvarli/Development/peacy/venv/lib/python3.10/site-packages/telegram/vendor/ptb_urllib3/urllib3/util/connection.py", line 60, in create_connection
    for res in socket.getaddrinfo(host, port, family, socket.SOCK_STREAM):
  File "/Users/canberkvarli/.pyenv/versions/3.10.4/lib/python3.10/socket.py", line 955, in getaddrinfo
    for res in _socket.getaddrinfo(host, port, family, type, proto, flags):
socket.gaierror: [Errno 8] nodename nor servname provided, or not known

During handling of the above exception, another exception occurred:

Traceback (most recent call last):
  File "/Users/canberkvarli/Development/peacy/venv/lib/python3.10/site-packages/telegram/vendor/ptb_urllib3/urllib3/connectionpool.py", line 614, in urlopen
    httplib_response = self._make_request(conn, method, url,
  File "/Users/canberkvarli/Development/peacy/venv/lib/python3.10/site-packages/telegram/vendor/ptb_urllib3/urllib3/connectionpool.py", line 360, in _make_request
    self._validate_conn(conn)
  File "/Users/canberkvarli/Development/peacy/venv/lib/python3.10/site-packages/telegram/vendor/ptb_urllib3/urllib3/connectionpool.py", line 857, in _validate_conn
    super(HTTPSConnectionPool, self)._validate_conn(conn)
  File "/Users/canberkvarli/Development/peacy/venv/lib/python3.10/site-packages/telegram/vendor/ptb_urllib3/urllib3/connectionpool.py", line 289, in _validate_conn
    conn.connect()
  File "/Users/canberkvarli/Development/peacy/venv/lib/python3.10/site-packages/telegram/vendor/ptb_urllib3/urllib3/connection.py", line 284, in connect
    conn = self._new_conn()
  File "/Users/canberkvarli/Development/peacy/venv/lib/python3.10/site-packages/telegram/vendor/ptb_urllib3/urllib3/connection.py", line 149, in _new_conn
    raise NewConnectionError(
telegram.vendor.ptb_urllib3.urllib3.exceptions.NewConnectionError: <telegram.vendor.ptb_urllib3.urllib3.connection.VerifiedHTTPSConnection object at 0x16f921930>: Failed to establish a new connection: [Errno 8] nodename nor servname provided, or not known

During handling of the above exception, another exception occurred:

Traceback (most recent call last):
  File "/Users/canberkvarli/Development/peacy/venv/lib/python3.10/site-packages/telegram/utils/request.py", line 259, in _request_wrapper
    resp = self._con_pool.request(*args, **kwargs)
  File "/Users/canberkvarli/Development/peacy/venv/lib/python3.10/site-packages/telegram/vendor/ptb_urllib3/urllib3/request.py", line 68, in request
    return self.request_encode_body(method, url, fields=fields,
  File "/Users/canberkvarli/Development/peacy/venv/lib/python3.10/site-packages/telegram/vendor/ptb_urllib3/urllib3/request.py", line 148, in request_encode_body
    return self.urlopen(method, url, **extra_kw)
  File "/Users/canberkvarli/Development/peacy/venv/lib/python3.10/site-packages/telegram/vendor/ptb_urllib3/urllib3/poolmanager.py", line 244, in urlopen
    response = conn.urlopen(method, u.request_uri, **kw)
  File "/Users/canberkvarli/Development/peacy/venv/lib/python3.10/site-packages/telegram/vendor/ptb_urllib3/urllib3/connectionpool.py", line 691, in urlopen
    return self.urlopen(method, url, body, headers, retries,
  File "/Users/canberkvarli/Development/peacy/venv/lib/python3.10/site-packages/telegram/vendor/ptb_urllib3/urllib3/connectionpool.py", line 691, in urlopen
    return self.urlopen(method, url, body, headers, retries,
  File "/Users/canberkvarli/Development/peacy/venv/lib/python3.10/site-packages/telegram/vendor/ptb_urllib3/urllib3/connectionpool.py", line 691, in urlopen
    return self.urlopen(method, url, body, headers, retries,
  File "/Users/canberkvarli/Development/peacy/venv/lib/python3.10/site-packages/telegram/vendor/ptb_urllib3/urllib3/connectionpool.py", line 665, in urlopen
    retries = retries.increment(method, url, error=e, _pool=self,
  File "/Users/canberkvarli/Development/peacy/venv/lib/python3.10/site-packages/telegram/vendor/ptb_urllib3/urllib3/util/retry.py", line 376, in increment
    raise MaxRetryError(_pool, url, error or ResponseError(cause))
telegram.vendor.ptb_urllib3.urllib3.exceptions.MaxRetryError: HTTPSConnectionPool(host='api.telegram.org', port=443): Max retries exceeded with url: /bot7327305156:AAGFKRpEVb48nB1PtSaLsPYRH8D-W9IVXiw/getUpdates (Caused by NewConnectionError('<telegram.vendor.ptb_urllib3.urllib3.connection.VerifiedHTTPSConnection object at 0x16f921930>: Failed to establish a new connection: [Errno 8] nodename nor servname provided, or not known'))

The above exception was the direct cause of the following exception:

Traceback (most recent call last):
  File "/Users/canberkvarli/Development/peacy/venv/lib/python3.10/site-packages/telegram/ext/updater.py", line 651, in _network_loop_retry
    if not action_cb():
  File "/Users/canberkvarli/Development/peacy/venv/lib/python3.10/site-packages/telegram/ext/updater.py", line 602, in polling_action_cb
    updates = self.bot.get_updates(
  File "/Users/canberkvarli/Development/peacy/venv/lib/python3.10/site-packages/telegram/ext/extbot.py", line 228, in get_updates
    updates = super().get_updates(
  File "/Users/canberkvarli/Development/peacy/venv/lib/python3.10/site-packages/telegram/bot.py", line 134, in decorator
    result = func(*args, **kwargs)
  File "/Users/canberkvarli/Development/peacy/venv/lib/python3.10/site-packages/telegram/bot.py", line 3140, in get_updates
    self._post(
  File "/Users/canberkvarli/Development/peacy/venv/lib/python3.10/site-packages/telegram/bot.py", line 299, in _post
    return self.request.post(
  File "/Users/canberkvarli/Development/peacy/venv/lib/python3.10/site-packages/telegram/utils/request.py", line 361, in post
    result = self._request_wrapper(
  File "/Users/canberkvarli/Development/peacy/venv/lib/python3.10/site-packages/telegram/utils/request.py", line 265, in _request_wrapper
    raise NetworkError(f'urllib3 HTTPError {error}') from error
telegram.error.NetworkError: urllib3 HTTPError HTTPSConnectionPool(host='api.telegram.org', port=443): Max retries exceeded with url: /bot7327305156:AAGFKRpEVb48nB1PtSaLsPYRH8D-W9IVXiw/getUpdates (Caused by NewConnectionError('<telegram.vendor.ptb_urllib3.urllib3.connection.VerifiedHTTPSConnection object at 0x16f921930>: Failed to establish a new connection: [Errno 8] nodename nor servname provided, or not known'))
WARNING:telegram.vendor.ptb_urllib3.urllib3.connectionpool:Retrying (Retry(total=2, connect=None, read=None, redirect=None)) after connection broken by 'NewConnectionError('<telegram.vendor.ptb_urllib3.urllib3.connection.VerifiedHTTPSConnection object at 0x16f920700>: Failed to establish a new connection: [Errno 8] nodename nor servname provided, or not known')': /bot7327305156:AAGFKRpEVb48nB1PtSaLsPYRH8D-W9IVXiw/getUpdates
WARNING:telegram.vendor.ptb_urllib3.urllib3.connectionpool:Retrying (Retry(total=1, connect=None, read=None, redirect=None)) after connection broken by 'NewConnectionError('<telegram.vendor.ptb_urllib3.urllib3.connection.VerifiedHTTPSConnection object at 0x16f922500>: Failed to establish a new connection: [Errno 8] nodename nor servname provided, or not known')': /bot7327305156:AAGFKRpEVb48nB1PtSaLsPYRH8D-W9IVXiw/getUpdates
WARNING:telegram.vendor.ptb_urllib3.urllib3.connectionpool:Retrying (Retry(total=0, connect=None, read=None, redirect=None)) after connection broken by 'NewConnectionError('<telegram.vendor.ptb_urllib3.urllib3.connection.VerifiedHTTPSConnection object at 0x16f922560>: Failed to establish a new connection: [Errno 8] nodename nor servname provided, or not known')': /bot7327305156:AAGFKRpEVb48nB1PtSaLsPYRH8D-W9IVXiw/getUpdates
ERROR:telegram.ext.updater:Error while getting Updates: urllib3 HTTPError HTTPSConnectionPool(host='api.telegram.org', port=443): Max retries exceeded with url: /bot7327305156:AAGFKRpEVb48nB1PtSaLsPYRH8D-W9IVXiw/getUpdates (Caused by NewConnectionError('<telegram.vendor.ptb_urllib3.urllib3.connection.VerifiedHTTPSConnection object at 0x16f922770>: Failed to establish a new connection: [Errno 8] nodename nor servname provided, or not known'))
ERROR:__main__:Exception in update:
Traceback (most recent call last):
  File "/Users/canberkvarli/Development/peacy/venv/lib/python3.10/site-packages/telegram/vendor/ptb_urllib3/urllib3/connection.py", line 140, in _new_conn
    conn = connection.create_connection(
  File "/Users/canberkvarli/Development/peacy/venv/lib/python3.10/site-packages/telegram/vendor/ptb_urllib3/urllib3/util/connection.py", line 60, in create_connection
    for res in socket.getaddrinfo(host, port, family, socket.SOCK_STREAM):
  File "/Users/canberkvarli/.pyenv/versions/3.10.4/lib/python3.10/socket.py", line 955, in getaddrinfo
    for res in _socket.getaddrinfo(host, port, family, type, proto, flags):
socket.gaierror: [Errno 8] nodename nor servname provided, or not known

During handling of the above exception, another exception occurred:

Traceback (most recent call last):
  File "/Users/canberkvarli/Development/peacy/venv/lib/python3.10/site-packages/telegram/vendor/ptb_urllib3/urllib3/connectionpool.py", line 614, in urlopen
    httplib_response = self._make_request(conn, method, url,
  File "/Users/canberkvarli/Development/peacy/venv/lib/python3.10/site-packages/telegram/vendor/ptb_urllib3/urllib3/connectionpool.py", line 360, in _make_request
    self._validate_conn(conn)
  File "/Users/canberkvarli/Development/peacy/venv/lib/python3.10/site-packages/telegram/vendor/ptb_urllib3/urllib3/connectionpool.py", line 857, in _validate_conn
    super(HTTPSConnectionPool, self)._validate_conn(conn)
  File "/Users/canberkvarli/Development/peacy/venv/lib/python3.10/site-packages/telegram/vendor/ptb_urllib3/urllib3/connectionpool.py", line 289, in _validate_conn
    conn.connect()
  File "/Users/canberkvarli/Development/peacy/venv/lib/python3.10/site-packages/telegram/vendor/ptb_urllib3/urllib3/connection.py", line 284, in connect
    conn = self._new_conn()
  File "/Users/canberkvarli/Development/peacy/venv/lib/python3.10/site-packages/telegram/vendor/ptb_urllib3/urllib3/connection.py", line 149, in _new_conn
    raise NewConnectionError(
telegram.vendor.ptb_urllib3.urllib3.exceptions.NewConnectionError: <telegram.vendor.ptb_urllib3.urllib3.connection.VerifiedHTTPSConnection object at 0x16f922770>: Failed to establish a new connection: [Errno 8] nodename nor servname provided, or not known

During handling of the above exception, another exception occurred:

Traceback (most recent call last):
  File "/Users/canberkvarli/Development/peacy/venv/lib/python3.10/site-packages/telegram/utils/request.py", line 259, in _request_wrapper
    resp = self._con_pool.request(*args, **kwargs)
  File "/Users/canberkvarli/Development/peacy/venv/lib/python3.10/site-packages/telegram/vendor/ptb_urllib3/urllib3/request.py", line 68, in request
    return self.request_encode_body(method, url, fields=fields,
  File "/Users/canberkvarli/Development/peacy/venv/lib/python3.10/site-packages/telegram/vendor/ptb_urllib3/urllib3/request.py", line 148, in request_encode_body
    return self.urlopen(method, url, **extra_kw)
  File "/Users/canberkvarli/Development/peacy/venv/lib/python3.10/site-packages/telegram/vendor/ptb_urllib3/urllib3/poolmanager.py", line 244, in urlopen
    response = conn.urlopen(method, u.request_uri, **kw)
  File "/Users/canberkvarli/Development/peacy/venv/lib/python3.10/site-packages/telegram/vendor/ptb_urllib3/urllib3/connectionpool.py", line 691, in urlopen
    return self.urlopen(method, url, body, headers, retries,
  File "/Users/canberkvarli/Development/peacy/venv/lib/python3.10/site-packages/telegram/vendor/ptb_urllib3/urllib3/connectionpool.py", line 691, in urlopen
    return self.urlopen(method, url, body, headers, retries,
  File "/Users/canberkvarli/Development/peacy/venv/lib/python3.10/site-packages/telegram/vendor/ptb_urllib3/urllib3/connectionpool.py", line 691, in urlopen
    return self.urlopen(method, url, body, headers, retries,
  File "/Users/canberkvarli/Development/peacy/venv/lib/python3.10/site-packages/telegram/vendor/ptb_urllib3/urllib3/connectionpool.py", line 665, in urlopen
    retries = retries.increment(method, url, error=e, _pool=self,
  File "/Users/canberkvarli/Development/peacy/venv/lib/python3.10/site-packages/telegram/vendor/ptb_urllib3/urllib3/util/retry.py", line 376, in increment
    raise MaxRetryError(_pool, url, error or ResponseError(cause))
telegram.vendor.ptb_urllib3.urllib3.exceptions.MaxRetryError: HTTPSConnectionPool(host='api.telegram.org', port=443): Max retries exceeded with url: /bot7327305156:AAGFKRpEVb48nB1PtSaLsPYRH8D-W9IVXiw/getUpdates (Caused by NewConnectionError('<telegram.vendor.ptb_urllib3.urllib3.connection.VerifiedHTTPSConnection object at 0x16f922770>: Failed to establish a new connection: [Errno 8] nodename nor servname provided, or not known'))

The above exception was the direct cause of the following exception:

Traceback (most recent call last):
  File "/Users/canberkvarli/Development/peacy/venv/lib/python3.10/site-packages/telegram/ext/updater.py", line 651, in _network_loop_retry
    if not action_cb():
  File "/Users/canberkvarli/Development/peacy/venv/lib/python3.10/site-packages/telegram/ext/updater.py", line 602, in polling_action_cb
    updates = self.bot.get_updates(
  File "/Users/canberkvarli/Development/peacy/venv/lib/python3.10/site-packages/telegram/ext/extbot.py", line 228, in get_updates
    updates = super().get_updates(
  File "/Users/canberkvarli/Development/peacy/venv/lib/python3.10/site-packages/telegram/bot.py", line 134, in decorator
    result = func(*args, **kwargs)
  File "/Users/canberkvarli/Development/peacy/venv/lib/python3.10/site-packages/telegram/bot.py", line 3140, in get_updates
    self._post(
  File "/Users/canberkvarli/Development/peacy/venv/lib/python3.10/site-packages/telegram/bot.py", line 299, in _post
    return self.request.post(
  File "/Users/canberkvarli/Development/peacy/venv/lib/python3.10/site-packages/telegram/utils/request.py", line 361, in post
    result = self._request_wrapper(
  File "/Users/canberkvarli/Development/peacy/venv/lib/python3.10/site-packages/telegram/utils/request.py", line 265, in _request_wrapper
    raise NetworkError(f'urllib3 HTTPError {error}') from error
telegram.error.NetworkError: urllib3 HTTPError HTTPSConnectionPool(host='api.telegram.org', port=443): Max retries exceeded with url: /bot7327305156:AAGFKRpEVb48nB1PtSaLsPYRH8D-W9IVXiw/getUpdates (Caused by NewConnectionError('<telegram.vendor.ptb_urllib3.urllib3.connection.VerifiedHTTPSConnection object at 0x16f922770>: Failed to establish a new connection: [Errno 8] nodename nor servname provided, or not known'))
WARNING:telegram.vendor.ptb_urllib3.urllib3.connectionpool:Retrying (Retry(total=2, connect=None, read=None, redirect=None)) after connection broken by 'NewConnectionError('<telegram.vendor.ptb_urllib3.urllib3.connection.VerifiedHTTPSConnection object at 0x16f922320>: Failed to establish a new connection: [Errno 8] nodename nor servname provided, or not known')': /bot7327305156:AAGFKRpEVb48nB1PtSaLsPYRH8D-W9IVXiw/getUpdates
WARNING:telegram.vendor.ptb_urllib3.urllib3.connectionpool:Retrying (Retry(total=1, connect=None, read=None, redirect=None)) after connection broken by 'NewConnectionError('<telegram.vendor.ptb_urllib3.urllib3.connection.VerifiedHTTPSConnection object at 0x16f9224d0>: Failed to establish a new connection: [Errno 8] nodename nor servname provided, or not known')': /bot7327305156:AAGFKRpEVb48nB1PtSaLsPYRH8D-W9IVXiw/getUpdates
WARNING:telegram.vendor.ptb_urllib3.urllib3.connectionpool:Retrying (Retry(total=0, connect=None, read=None, redirect=None)) after connection broken by 'NewConnectionError('<telegram.vendor.ptb_urllib3.urllib3.connection.VerifiedHTTPSConnection object at 0x16f922c50>: Failed to establish a new connection: [Errno 8] nodename nor servname provided, or not known')': /bot7327305156:AAGFKRpEVb48nB1PtSaLsPYRH8D-W9IVXiw/getUpdates
ERROR:telegram.ext.updater:Error while getting Updates: urllib3 HTTPError HTTPSConnectionPool(host='api.telegram.org', port=443): Max retries exceeded with url: /bot7327305156:AAGFKRpEVb48nB1PtSaLsPYRH8D-W9IVXiw/getUpdates (Caused by NewConnectionError('<telegram.vendor.ptb_urllib3.urllib3.connection.VerifiedHTTPSConnection object at 0x16f922da0>: Failed to establish a new connection: [Errno 8] nodename nor servname provided, or not known'))
ERROR:__main__:Exception in update:
Traceback (most recent call last):
  File "/Users/canberkvarli/Development/peacy/venv/lib/python3.10/site-packages/telegram/vendor/ptb_urllib3/urllib3/connection.py", line 140, in _new_conn
    conn = connection.create_connection(
  File "/Users/canberkvarli/Development/peacy/venv/lib/python3.10/site-packages/telegram/vendor/ptb_urllib3/urllib3/util/connection.py", line 60, in create_connection
    for res in socket.getaddrinfo(host, port, family, socket.SOCK_STREAM):
  File "/Users/canberkvarli/.pyenv/versions/3.10.4/lib/python3.10/socket.py", line 955, in getaddrinfo
    for res in _socket.getaddrinfo(host, port, family, type, proto, flags):
socket.gaierror: [Errno 8] nodename nor servname provided, or not known

During handling of the above exception, another exception occurred:

Traceback (most recent call last):
  File "/Users/canberkvarli/Development/peacy/venv/lib/python3.10/site-packages/telegram/vendor/ptb_urllib3/urllib3/connectionpool.py", line 614, in urlopen
    httplib_response = self._make_request(conn, method, url,
  File "/Users/canberkvarli/Development/peacy/venv/lib/python3.10/site-packages/telegram/vendor/ptb_urllib3/urllib3/connectionpool.py", line 360, in _make_request
    self._validate_conn(conn)
  File "/Users/canberkvarli/Development/peacy/venv/lib/python3.10/site-packages/telegram/vendor/ptb_urllib3/urllib3/connectionpool.py", line 857, in _validate_conn
    super(HTTPSConnectionPool, self)._validate_conn(conn)
  File "/Users/canberkvarli/Development/peacy/venv/lib/python3.10/site-packages/telegram/vendor/ptb_urllib3/urllib3/connectionpool.py", line 289, in _validate_conn
    conn.connect()
  File "/Users/canberkvarli/Development/peacy/venv/lib/python3.10/site-packages/telegram/vendor/ptb_urllib3/urllib3/connection.py", line 284, in connect
    conn = self._new_conn()
  File "/Users/canberkvarli/Development/peacy/venv/lib/python3.10/site-packages/telegram/vendor/ptb_urllib3/urllib3/connection.py", line 149, in _new_conn
    raise NewConnectionError(
telegram.vendor.ptb_urllib3.urllib3.exceptions.NewConnectionError: <telegram.vendor.ptb_urllib3.urllib3.connection.VerifiedHTTPSConnection object at 0x16f922da0>: Failed to establish a new connection: [Errno 8] nodename nor servname provided, or not known

During handling of the above exception, another exception occurred:

Traceback (most recent call last):
  File "/Users/canberkvarli/Development/peacy/venv/lib/python3.10/site-packages/telegram/utils/request.py", line 259, in _request_wrapper
    resp = self._con_pool.request(*args, **kwargs)
  File "/Users/canberkvarli/Development/peacy/venv/lib/python3.10/site-packages/telegram/vendor/ptb_urllib3/urllib3/request.py", line 68, in request
    return self.request_encode_body(method, url, fields=fields,
  File "/Users/canberkvarli/Development/peacy/venv/lib/python3.10/site-packages/telegram/vendor/ptb_urllib3/urllib3/request.py", line 148, in request_encode_body
    return self.urlopen(method, url, **extra_kw)
  File "/Users/canberkvarli/Development/peacy/venv/lib/python3.10/site-packages/telegram/vendor/ptb_urllib3/urllib3/poolmanager.py", line 244, in urlopen
    response = conn.urlopen(method, u.request_uri, **kw)
  File "/Users/canberkvarli/Development/peacy/venv/lib/python3.10/site-packages/telegram/vendor/ptb_urllib3/urllib3/connectionpool.py", line 691, in urlopen
    return self.urlopen(method, url, body, headers, retries,
  File "/Users/canberkvarli/Development/peacy/venv/lib/python3.10/site-packages/telegram/vendor/ptb_urllib3/urllib3/connectionpool.py", line 691, in urlopen
    return self.urlopen(method, url, body, headers, retries,
  File "/Users/canberkvarli/Development/peacy/venv/lib/python3.10/site-packages/telegram/vendor/ptb_urllib3/urllib3/connectionpool.py", line 691, in urlopen
    return self.urlopen(method, url, body, headers, retries,
  File "/Users/canberkvarli/Development/peacy/venv/lib/python3.10/site-packages/telegram/vendor/ptb_urllib3/urllib3/connectionpool.py", line 665, in urlopen
    retries = retries.increment(method, url, error=e, _pool=self,
  File "/Users/canberkvarli/Development/peacy/venv/lib/python3.10/site-packages/telegram/vendor/ptb_urllib3/urllib3/util/retry.py", line 376, in increment
    raise MaxRetryError(_pool, url, error or ResponseError(cause))
telegram.vendor.ptb_urllib3.urllib3.exceptions.MaxRetryError: HTTPSConnectionPool(host='api.telegram.org', port=443): Max retries exceeded with url: /bot7327305156:AAGFKRpEVb48nB1PtSaLsPYRH8D-W9IVXiw/getUpdates (Caused by NewConnectionError('<telegram.vendor.ptb_urllib3.urllib3.connection.VerifiedHTTPSConnection object at 0x16f922da0>: Failed to establish a new connection: [Errno 8] nodename nor servname provided, or not known'))

The above exception was the direct cause of the following exception:

Traceback (most recent call last):
  File "/Users/canberkvarli/Development/peacy/venv/lib/python3.10/site-packages/telegram/ext/updater.py", line 651, in _network_loop_retry
    if not action_cb():
  File "/Users/canberkvarli/Development/peacy/venv/lib/python3.10/site-packages/telegram/ext/updater.py", line 602, in polling_action_cb
    updates = self.bot.get_updates(
  File "/Users/canberkvarli/Development/peacy/venv/lib/python3.10/site-packages/telegram/ext/extbot.py", line 228, in get_updates
    updates = super().get_updates(
  File "/Users/canberkvarli/Development/peacy/venv/lib/python3.10/site-packages/telegram/bot.py", line 134, in decorator
    result = func(*args, **kwargs)
  File "/Users/canberkvarli/Development/peacy/venv/lib/python3.10/site-packages/telegram/bot.py", line 3140, in get_updates
    self._post(
  File "/Users/canberkvarli/Development/peacy/venv/lib/python3.10/site-packages/telegram/bot.py", line 299, in _post
    return self.request.post(
  File "/Users/canberkvarli/Development/peacy/venv/lib/python3.10/site-packages/telegram/utils/request.py", line 361, in post
    result = self._request_wrapper(
  File "/Users/canberkvarli/Development/peacy/venv/lib/python3.10/site-packages/telegram/utils/request.py", line 265, in _request_wrapper
    raise NetworkError(f'urllib3 HTTPError {error}') from error
telegram.error.NetworkError: urllib3 HTTPError HTTPSConnectionPool(host='api.telegram.org', port=443): Max retries exceeded with url: /bot7327305156:AAGFKRpEVb48nB1PtSaLsPYRH8D-W9IVXiw/getUpdates (Caused by NewConnectionError('<telegram.vendor.ptb_urllib3.urllib3.connection.VerifiedHTTPSConnection object at 0x16f922da0>: Failed to establish a new connection: [Errno 8] nodename nor servname provided, or not known'))
WARNING:telegram.vendor.ptb_urllib3.urllib3.connectionpool:Retrying (Retry(total=2, connect=None, read=None, redirect=None)) after connection broken by 'NewConnectionError('<telegram.vendor.ptb_urllib3.urllib3.connection.VerifiedHTTPSConnection object at 0x16f922740>: Failed to establish a new connection: [Errno 8] nodename nor servname provided, or not known')': /bot7327305156:AAGFKRpEVb48nB1PtSaLsPYRH8D-W9IVXiw/getUpdates
WARNING:telegram.vendor.ptb_urllib3.urllib3.connectionpool:Retrying (Retry(total=1, connect=None, read=None, redirect=None)) after connection broken by 'NewConnectionError('<telegram.vendor.ptb_urllib3.urllib3.connection.VerifiedHTTPSConnection object at 0x16f922f50>: Failed to establish a new connection: [Errno 8] nodename nor servname provided, or not known')': /bot7327305156:AAGFKRpEVb48nB1PtSaLsPYRH8D-W9IVXiw/getUpdates
WARNING:telegram.vendor.ptb_urllib3.urllib3.connectionpool:Retrying (Retry(total=0, connect=None, read=None, redirect=None)) after connection broken by 'NewConnectionError('<telegram.vendor.ptb_urllib3.urllib3.connection.VerifiedHTTPSConnection object at 0x30dd7c040>: Failed to establish a new connection: [Errno 8] nodename nor servname provided, or not known')': /bot7327305156:AAGFKRpEVb48nB1PtSaLsPYRH8D-W9IVXiw/getUpdates
ERROR:telegram.ext.updater:Error while getting Updates: urllib3 HTTPError HTTPSConnectionPool(host='api.telegram.org', port=443): Max retries exceeded with url: /bot7327305156:AAGFKRpEVb48nB1PtSaLsPYRH8D-W9IVXiw/getUpdates (Caused by NewConnectionError('<telegram.vendor.ptb_urllib3.urllib3.connection.VerifiedHTTPSConnection object at 0x30dd7fe50>: Failed to establish a new connection: [Errno 8] nodename nor servname provided, or not known'))
ERROR:__main__:Exception in update:
Traceback (most recent call last):
  File "/Users/canberkvarli/Development/peacy/venv/lib/python3.10/site-packages/telegram/vendor/ptb_urllib3/urllib3/connection.py", line 140, in _new_conn
    conn = connection.create_connection(
  File "/Users/canberkvarli/Development/peacy/venv/lib/python3.10/site-packages/telegram/vendor/ptb_urllib3/urllib3/util/connection.py", line 60, in create_connection
    for res in socket.getaddrinfo(host, port, family, socket.SOCK_STREAM):
  File "/Users/canberkvarli/.pyenv/versions/3.10.4/lib/python3.10/socket.py", line 955, in getaddrinfo
    for res in _socket.getaddrinfo(host, port, family, type, proto, flags):
socket.gaierror: [Errno 8] nodename nor servname provided, or not known

During handling of the above exception, another exception occurred:

Traceback (most recent call last):
  File "/Users/canberkvarli/Development/peacy/venv/lib/python3.10/site-packages/telegram/vendor/ptb_urllib3/urllib3/connectionpool.py", line 614, in urlopen
    httplib_response = self._make_request(conn, method, url,
  File "/Users/canberkvarli/Development/peacy/venv/lib/python3.10/site-packages/telegram/vendor/ptb_urllib3/urllib3/connectionpool.py", line 360, in _make_request
    self._validate_conn(conn)
  File "/Users/canberkvarli/Development/peacy/venv/lib/python3.10/site-packages/telegram/vendor/ptb_urllib3/urllib3/connectionpool.py", line 857, in _validate_conn
    super(HTTPSConnectionPool, self)._validate_conn(conn)
  File "/Users/canberkvarli/Development/peacy/venv/lib/python3.10/site-packages/telegram/vendor/ptb_urllib3/urllib3/connectionpool.py", line 289, in _validate_conn
    conn.connect()
  File "/Users/canberkvarli/Development/peacy/venv/lib/python3.10/site-packages/telegram/vendor/ptb_urllib3/urllib3/connection.py", line 284, in connect
    conn = self._new_conn()
  File "/Users/canberkvarli/Development/peacy/venv/lib/python3.10/site-packages/telegram/vendor/ptb_urllib3/urllib3/connection.py", line 149, in _new_conn
    raise NewConnectionError(
telegram.vendor.ptb_urllib3.urllib3.exceptions.NewConnectionError: <telegram.vendor.ptb_urllib3.urllib3.connection.VerifiedHTTPSConnection object at 0x30dd7fe50>: Failed to establish a new connection: [Errno 8] nodename nor servname provided, or not known

During handling of the above exception, another exception occurred:

Traceback (most recent call last):
  File "/Users/canberkvarli/Development/peacy/venv/lib/python3.10/site-packages/telegram/utils/request.py", line 259, in _request_wrapper
    resp = self._con_pool.request(*args, **kwargs)
  File "/Users/canberkvarli/Development/peacy/venv/lib/python3.10/site-packages/telegram/vendor/ptb_urllib3/urllib3/request.py", line 68, in request
    return self.request_encode_body(method, url, fields=fields,
  File "/Users/canberkvarli/Development/peacy/venv/lib/python3.10/site-packages/telegram/vendor/ptb_urllib3/urllib3/request.py", line 148, in request_encode_body
    return self.urlopen(method, url, **extra_kw)
  File "/Users/canberkvarli/Development/peacy/venv/lib/python3.10/site-packages/telegram/vendor/ptb_urllib3/urllib3/poolmanager.py", line 244, in urlopen
    response = conn.urlopen(method, u.request_uri, **kw)
  File "/Users/canberkvarli/Development/peacy/venv/lib/python3.10/site-packages/telegram/vendor/ptb_urllib3/urllib3/connectionpool.py", line 691, in urlopen
    return self.urlopen(method, url, body, headers, retries,
  File "/Users/canberkvarli/Development/peacy/venv/lib/python3.10/site-packages/telegram/vendor/ptb_urllib3/urllib3/connectionpool.py", line 691, in urlopen
    return self.urlopen(method, url, body, headers, retries,
  File "/Users/canberkvarli/Development/peacy/venv/lib/python3.10/site-packages/telegram/vendor/ptb_urllib3/urllib3/connectionpool.py", line 691, in urlopen
    return self.urlopen(method, url, body, headers, retries,
  File "/Users/canberkvarli/Development/peacy/venv/lib/python3.10/site-packages/telegram/vendor/ptb_urllib3/urllib3/connectionpool.py", line 665, in urlopen
    retries = retries.increment(method, url, error=e, _pool=self,
  File "/Users/canberkvarli/Development/peacy/venv/lib/python3.10/site-packages/telegram/vendor/ptb_urllib3/urllib3/util/retry.py", line 376, in increment
    raise MaxRetryError(_pool, url, error or ResponseError(cause))
telegram.vendor.ptb_urllib3.urllib3.exceptions.MaxRetryError: HTTPSConnectionPool(host='api.telegram.org', port=443): Max retries exceeded with url: /bot7327305156:AAGFKRpEVb48nB1PtSaLsPYRH8D-W9IVXiw/getUpdates (Caused by NewConnectionError('<telegram.vendor.ptb_urllib3.urllib3.connection.VerifiedHTTPSConnection object at 0x30dd7fe50>: Failed to establish a new connection: [Errno 8] nodename nor servname provided, or not known'))

The above exception was the direct cause of the following exception:

Traceback (most recent call last):
  File "/Users/canberkvarli/Development/peacy/venv/lib/python3.10/site-packages/telegram/ext/updater.py", line 651, in _network_loop_retry
    if not action_cb():
  File "/Users/canberkvarli/Development/peacy/venv/lib/python3.10/site-packages/telegram/ext/updater.py", line 602, in polling_action_cb
    updates = self.bot.get_updates(
  File "/Users/canberkvarli/Development/peacy/venv/lib/python3.10/site-packages/telegram/ext/extbot.py", line 228, in get_updates
    updates = super().get_updates(
  File "/Users/canberkvarli/Development/peacy/venv/lib/python3.10/site-packages/telegram/bot.py", line 134, in decorator
    result = func(*args, **kwargs)
  File "/Users/canberkvarli/Development/peacy/venv/lib/python3.10/site-packages/telegram/bot.py", line 3140, in get_updates
    self._post(
  File "/Users/canberkvarli/Development/peacy/venv/lib/python3.10/site-packages/telegram/bot.py", line 299, in _post
    return self.request.post(
  File "/Users/canberkvarli/Development/peacy/venv/lib/python3.10/site-packages/telegram/utils/request.py", line 361, in post
    result = self._request_wrapper(
  File "/Users/canberkvarli/Development/peacy/venv/lib/python3.10/site-packages/telegram/utils/request.py", line 265, in _request_wrapper
    raise NetworkError(f'urllib3 HTTPError {error}') from error
telegram.error.NetworkError: urllib3 HTTPError HTTPSConnectionPool(host='api.telegram.org', port=443): Max retries exceeded with url: /bot7327305156:AAGFKRpEVb48nB1PtSaLsPYRH8D-W9IVXiw/getUpdates (Caused by NewConnectionError('<telegram.vendor.ptb_urllib3.urllib3.connection.VerifiedHTTPSConnection object at 0x30dd7fe50>: Failed to establish a new connection: [Errno 8] nodename nor servname provided, or not known'))
WARNING:telegram.vendor.ptb_urllib3.urllib3.connectionpool:Retrying (Retry(total=2, connect=None, read=None, redirect=None)) after connection broken by 'NewConnectionError('<telegram.vendor.ptb_urllib3.urllib3.connection.VerifiedHTTPSConnection object at 0x16f922ec0>: Failed to establish a new connection: [Errno 8] nodename nor servname provided, or not known')': /bot7327305156:AAGFKRpEVb48nB1PtSaLsPYRH8D-W9IVXiw/getUpdates
WARNING:telegram.vendor.ptb_urllib3.urllib3.connectionpool:Retrying (Retry(total=1, connect=None, read=None, redirect=None)) after connection broken by 'NewConnectionError('<telegram.vendor.ptb_urllib3.urllib3.connection.VerifiedHTTPSConnection object at 0x16f922770>: Failed to establish a new connection: [Errno 8] nodename nor servname provided, or not known')': /bot7327305156:AAGFKRpEVb48nB1PtSaLsPYRH8D-W9IVXiw/getUpdates
WARNING:telegram.vendor.ptb_urllib3.urllib3.connectionpool:Retrying (Retry(total=0, connect=None, read=None, redirect=None)) after connection broken by 'NewConnectionError('<telegram.vendor.ptb_urllib3.urllib3.connection.VerifiedHTTPSConnection object at 0x16f9226b0>: Failed to establish a new connection: [Errno 8] nodename nor servname provided, or not known')': /bot7327305156:AAGFKRpEVb48nB1PtSaLsPYRH8D-W9IVXiw/getUpdates
ERROR:telegram.ext.updater:Error while getting Updates: urllib3 HTTPError HTTPSConnectionPool(host='api.telegram.org', port=443): Max retries exceeded with url: /bot7327305156:AAGFKRpEVb48nB1PtSaLsPYRH8D-W9IVXiw/getUpdates (Caused by NewConnectionError('<telegram.vendor.ptb_urllib3.urllib3.connection.VerifiedHTTPSConnection object at 0x16f922500>: Failed to establish a new connection: [Errno 8] nodename nor servname provided, or not known'))
ERROR:__main__:Exception in update:
Traceback (most recent call last):
  File "/Users/canberkvarli/Development/peacy/venv/lib/python3.10/site-packages/telegram/vendor/ptb_urllib3/urllib3/connection.py", line 140, in _new_conn
    conn = connection.create_connection(
  File "/Users/canberkvarli/Development/peacy/venv/lib/python3.10/site-packages/telegram/vendor/ptb_urllib3/urllib3/util/connection.py", line 60, in create_connection
    for res in socket.getaddrinfo(host, port, family, socket.SOCK_STREAM):
  File "/Users/canberkvarli/.pyenv/versions/3.10.4/lib/python3.10/socket.py", line 955, in getaddrinfo
    for res in _socket.getaddrinfo(host, port, family, type, proto, flags):
socket.gaierror: [Errno 8] nodename nor servname provided, or not known

During handling of the above exception, another exception occurred:

Traceback (most recent call last):
  File "/Users/canberkvarli/Development/peacy/venv/lib/python3.10/site-packages/telegram/vendor/ptb_urllib3/urllib3/connectionpool.py", line 614, in urlopen
    httplib_response = self._make_request(conn, method, url,
  File "/Users/canberkvarli/Development/peacy/venv/lib/python3.10/site-packages/telegram/vendor/ptb_urllib3/urllib3/connectionpool.py", line 360, in _make_request
    self._validate_conn(conn)
  File "/Users/canberkvarli/Development/peacy/venv/lib/python3.10/site-packages/telegram/vendor/ptb_urllib3/urllib3/connectionpool.py", line 857, in _validate_conn
    super(HTTPSConnectionPool, self)._validate_conn(conn)
  File "/Users/canberkvarli/Development/peacy/venv/lib/python3.10/site-packages/telegram/vendor/ptb_urllib3/urllib3/connectionpool.py", line 289, in _validate_conn
    conn.connect()
  File "/Users/canberkvarli/Development/peacy/venv/lib/python3.10/site-packages/telegram/vendor/ptb_urllib3/urllib3/connection.py", line 284, in connect
    conn = self._new_conn()
  File "/Users/canberkvarli/Development/peacy/venv/lib/python3.10/site-packages/telegram/vendor/ptb_urllib3/urllib3/connection.py", line 149, in _new_conn
    raise NewConnectionError(
telegram.vendor.ptb_urllib3.urllib3.exceptions.NewConnectionError: <telegram.vendor.ptb_urllib3.urllib3.connection.VerifiedHTTPSConnection object at 0x16f922500>: Failed to establish a new connection: [Errno 8] nodename nor servname provided, or not known

During handling of the above exception, another exception occurred:

Traceback (most recent call last):
  File "/Users/canberkvarli/Development/peacy/venv/lib/python3.10/site-packages/telegram/utils/request.py", line 259, in _request_wrapper
    resp = self._con_pool.request(*args, **kwargs)
  File "/Users/canberkvarli/Development/peacy/venv/lib/python3.10/site-packages/telegram/vendor/ptb_urllib3/urllib3/request.py", line 68, in request
    return self.request_encode_body(method, url, fields=fields,
  File "/Users/canberkvarli/Development/peacy/venv/lib/python3.10/site-packages/telegram/vendor/ptb_urllib3/urllib3/request.py", line 148, in request_encode_body
    return self.urlopen(method, url, **extra_kw)
  File "/Users/canberkvarli/Development/peacy/venv/lib/python3.10/site-packages/telegram/vendor/ptb_urllib3/urllib3/poolmanager.py", line 244, in urlopen
    response = conn.urlopen(method, u.request_uri, **kw)
  File "/Users/canberkvarli/Development/peacy/venv/lib/python3.10/site-packages/telegram/vendor/ptb_urllib3/urllib3/connectionpool.py", line 691, in urlopen
    return self.urlopen(method, url, body, headers, retries,
  File "/Users/canberkvarli/Development/peacy/venv/lib/python3.10/site-packages/telegram/vendor/ptb_urllib3/urllib3/connectionpool.py", line 691, in urlopen
    return self.urlopen(method, url, body, headers, retries,
  File "/Users/canberkvarli/Development/peacy/venv/lib/python3.10/site-packages/telegram/vendor/ptb_urllib3/urllib3/connectionpool.py", line 691, in urlopen
    return self.urlopen(method, url, body, headers, retries,
  File "/Users/canberkvarli/Development/peacy/venv/lib/python3.10/site-packages/telegram/vendor/ptb_urllib3/urllib3/connectionpool.py", line 665, in urlopen
    retries = retries.increment(method, url, error=e, _pool=self,
  File "/Users/canberkvarli/Development/peacy/venv/lib/python3.10/site-packages/telegram/vendor/ptb_urllib3/urllib3/util/retry.py", line 376, in increment
    raise MaxRetryError(_pool, url, error or ResponseError(cause))
telegram.vendor.ptb_urllib3.urllib3.exceptions.MaxRetryError: HTTPSConnectionPool(host='api.telegram.org', port=443): Max retries exceeded with url: /bot7327305156:AAGFKRpEVb48nB1PtSaLsPYRH8D-W9IVXiw/getUpdates (Caused by NewConnectionError('<telegram.vendor.ptb_urllib3.urllib3.connection.VerifiedHTTPSConnection object at 0x16f922500>: Failed to establish a new connection: [Errno 8] nodename nor servname provided, or not known'))

The above exception was the direct cause of the following exception:

Traceback (most recent call last):
  File "/Users/canberkvarli/Development/peacy/venv/lib/python3.10/site-packages/telegram/ext/updater.py", line 651, in _network_loop_retry
    if not action_cb():
  File "/Users/canberkvarli/Development/peacy/venv/lib/python3.10/site-packages/telegram/ext/updater.py", line 602, in polling_action_cb
    updates = self.bot.get_updates(
  File "/Users/canberkvarli/Development/peacy/venv/lib/python3.10/site-packages/telegram/ext/extbot.py", line 228, in get_updates
    updates = super().get_updates(
  File "/Users/canberkvarli/Development/peacy/venv/lib/python3.10/site-packages/telegram/bot.py", line 134, in decorator
    result = func(*args, **kwargs)
  File "/Users/canberkvarli/Development/peacy/venv/lib/python3.10/site-packages/telegram/bot.py", line 3140, in get_updates
    self._post(
  File "/Users/canberkvarli/Development/peacy/venv/lib/python3.10/site-packages/telegram/bot.py", line 299, in _post
    return self.request.post(
  File "/Users/canberkvarli/Development/peacy/venv/lib/python3.10/site-packages/telegram/utils/request.py", line 361, in post
    result = self._request_wrapper(
  File "/Users/canberkvarli/Development/peacy/venv/lib/python3.10/site-packages/telegram/utils/request.py", line 265, in _request_wrapper
    raise NetworkError(f'urllib3 HTTPError {error}') from error
telegram.error.NetworkError: urllib3 HTTPError HTTPSConnectionPool(host='api.telegram.org', port=443): Max retries exceeded with url: /bot7327305156:AAGFKRpEVb48nB1PtSaLsPYRH8D-W9IVXiw/getUpdates (Caused by NewConnectionError('<telegram.vendor.ptb_urllib3.urllib3.connection.VerifiedHTTPSConnection object at 0x16f922500>: Failed to establish a new connection: [Errno 8] nodename nor servname provided, or not known'))
WARNING:telegram.vendor.ptb_urllib3.urllib3.connectionpool:Retrying (Retry(total=2, connect=None, read=None, redirect=None)) after connection broken by 'NewConnectionError('<telegram.vendor.ptb_urllib3.urllib3.connection.VerifiedHTTPSConnection object at 0x30dd7e8f0>: Failed to establish a new connection: [Errno 8] nodename nor servname provided, or not known')': /bot7327305156:AAGFKRpEVb48nB1PtSaLsPYRH8D-W9IVXiw/getUpdates
WARNING:telegram.vendor.ptb_urllib3.urllib3.connectionpool:Retrying (Retry(total=1, connect=None, read=None, redirect=None)) after connection broken by 'NewConnectionError('<telegram.vendor.ptb_urllib3.urllib3.connection.VerifiedHTTPSConnection object at 0x16f920eb0>: Failed to establish a new connection: [Errno 8] nodename nor servname provided, or not known')': /bot7327305156:AAGFKRpEVb48nB1PtSaLsPYRH8D-W9IVXiw/getUpdates
WARNING:telegram.vendor.ptb_urllib3.urllib3.connectionpool:Retrying (Retry(total=0, connect=None, read=None, redirect=None)) after connection broken by 'NewConnectionError('<telegram.vendor.ptb_urllib3.urllib3.connection.VerifiedHTTPSConnection object at 0x16f920c40>: Failed to establish a new connection: [Errno 8] nodename nor servname provided, or not known')': /bot7327305156:AAGFKRpEVb48nB1PtSaLsPYRH8D-W9IVXiw/getUpdates
ERROR:telegram.ext.updater:Error while getting Updates: urllib3 HTTPError HTTPSConnectionPool(host='api.telegram.org', port=443): Max retries exceeded with url: /bot7327305156:AAGFKRpEVb48nB1PtSaLsPYRH8D-W9IVXiw/getUpdates (Caused by NewConnectionError('<telegram.vendor.ptb_urllib3.urllib3.connection.VerifiedHTTPSConnection object at 0x16f922440>: Failed to establish a new connection: [Errno 8] nodename nor servname provided, or not known'))
ERROR:__main__:Exception in update:
Traceback (most recent call last):
  File "/Users/canberkvarli/Development/peacy/venv/lib/python3.10/site-packages/telegram/vendor/ptb_urllib3/urllib3/connection.py", line 140, in _new_conn
    conn = connection.create_connection(
  File "/Users/canberkvarli/Development/peacy/venv/lib/python3.10/site-packages/telegram/vendor/ptb_urllib3/urllib3/util/connection.py", line 60, in create_connection
    for res in socket.getaddrinfo(host, port, family, socket.SOCK_STREAM):
  File "/Users/canberkvarli/.pyenv/versions/3.10.4/lib/python3.10/socket.py", line 955, in getaddrinfo
    for res in _socket.getaddrinfo(host, port, family, type, proto, flags):
socket.gaierror: [Errno 8] nodename nor servname provided, or not known

During handling of the above exception, another exception occurred:

Traceback (most recent call last):
  File "/Users/canberkvarli/Development/peacy/venv/lib/python3.10/site-packages/telegram/vendor/ptb_urllib3/urllib3/connectionpool.py", line 614, in urlopen
    httplib_response = self._make_request(conn, method, url,
  File "/Users/canberkvarli/Development/peacy/venv/lib/python3.10/site-packages/telegram/vendor/ptb_urllib3/urllib3/connectionpool.py", line 360, in _make_request
    self._validate_conn(conn)
  File "/Users/canberkvarli/Development/peacy/venv/lib/python3.10/site-packages/telegram/vendor/ptb_urllib3/urllib3/connectionpool.py", line 857, in _validate_conn
    super(HTTPSConnectionPool, self)._validate_conn(conn)
  File "/Users/canberkvarli/Development/peacy/venv/lib/python3.10/site-packages/telegram/vendor/ptb_urllib3/urllib3/connectionpool.py", line 289, in _validate_conn
    conn.connect()
  File "/Users/canberkvarli/Development/peacy/venv/lib/python3.10/site-packages/telegram/vendor/ptb_urllib3/urllib3/connection.py", line 284, in connect
    conn = self._new_conn()
  File "/Users/canberkvarli/Development/peacy/venv/lib/python3.10/site-packages/telegram/vendor/ptb_urllib3/urllib3/connection.py", line 149, in _new_conn
    raise NewConnectionError(
telegram.vendor.ptb_urllib3.urllib3.exceptions.NewConnectionError: <telegram.vendor.ptb_urllib3.urllib3.connection.VerifiedHTTPSConnection object at 0x16f922440>: Failed to establish a new connection: [Errno 8] nodename nor servname provided, or not known

During handling of the above exception, another exception occurred:

Traceback (most recent call last):
  File "/Users/canberkvarli/Development/peacy/venv/lib/python3.10/site-packages/telegram/utils/request.py", line 259, in _request_wrapper
    resp = self._con_pool.request(*args, **kwargs)
  File "/Users/canberkvarli/Development/peacy/venv/lib/python3.10/site-packages/telegram/vendor/ptb_urllib3/urllib3/request.py", line 68, in request
    return self.request_encode_body(method, url, fields=fields,
  File "/Users/canberkvarli/Development/peacy/venv/lib/python3.10/site-packages/telegram/vendor/ptb_urllib3/urllib3/request.py", line 148, in request_encode_body
    return self.urlopen(method, url, **extra_kw)
  File "/Users/canberkvarli/Development/peacy/venv/lib/python3.10/site-packages/telegram/vendor/ptb_urllib3/urllib3/poolmanager.py", line 244, in urlopen
    response = conn.urlopen(method, u.request_uri, **kw)
  File "/Users/canberkvarli/Development/peacy/venv/lib/python3.10/site-packages/telegram/vendor/ptb_urllib3/urllib3/connectionpool.py", line 691, in urlopen
    return self.urlopen(method, url, body, headers, retries,
  File "/Users/canberkvarli/Development/peacy/venv/lib/python3.10/site-packages/telegram/vendor/ptb_urllib3/urllib3/connectionpool.py", line 691, in urlopen
    return self.urlopen(method, url, body, headers, retries,
  File "/Users/canberkvarli/Development/peacy/venv/lib/python3.10/site-packages/telegram/vendor/ptb_urllib3/urllib3/connectionpool.py", line 691, in urlopen
    return self.urlopen(method, url, body, headers, retries,
  File "/Users/canberkvarli/Development/peacy/venv/lib/python3.10/site-packages/telegram/vendor/ptb_urllib3/urllib3/connectionpool.py", line 665, in urlopen
    retries = retries.increment(method, url, error=e, _pool=self,
  File "/Users/canberkvarli/Development/peacy/venv/lib/python3.10/site-packages/telegram/vendor/ptb_urllib3/urllib3/util/retry.py", line 376, in increment
    raise MaxRetryError(_pool, url, error or ResponseError(cause))
telegram.vendor.ptb_urllib3.urllib3.exceptions.MaxRetryError: HTTPSConnectionPool(host='api.telegram.org', port=443): Max retries exceeded with url: /bot7327305156:AAGFKRpEVb48nB1PtSaLsPYRH8D-W9IVXiw/getUpdates (Caused by NewConnectionError('<telegram.vendor.ptb_urllib3.urllib3.connection.VerifiedHTTPSConnection object at 0x16f922440>: Failed to establish a new connection: [Errno 8] nodename nor servname provided, or not known'))

The above exception was the direct cause of the following exception:

Traceback (most recent call last):
  File "/Users/canberkvarli/Development/peacy/venv/lib/python3.10/site-packages/telegram/ext/updater.py", line 651, in _network_loop_retry
    if not action_cb():
  File "/Users/canberkvarli/Development/peacy/venv/lib/python3.10/site-packages/telegram/ext/updater.py", line 602, in polling_action_cb
    updates = self.bot.get_updates(
  File "/Users/canberkvarli/Development/peacy/venv/lib/python3.10/site-packages/telegram/ext/extbot.py", line 228, in get_updates
    updates = super().get_updates(
  File "/Users/canberkvarli/Development/peacy/venv/lib/python3.10/site-packages/telegram/bot.py", line 134, in decorator
    result = func(*args, **kwargs)
  File "/Users/canberkvarli/Development/peacy/venv/lib/python3.10/site-packages/telegram/bot.py", line 3140, in get_updates
    self._post(
  File "/Users/canberkvarli/Development/peacy/venv/lib/python3.10/site-packages/telegram/bot.py", line 299, in _post
    return self.request.post(
  File "/Users/canberkvarli/Development/peacy/venv/lib/python3.10/site-packages/telegram/utils/request.py", line 361, in post
    result = self._request_wrapper(
  File "/Users/canberkvarli/Development/peacy/venv/lib/python3.10/site-packages/telegram/utils/request.py", line 265, in _request_wrapper
    raise NetworkError(f'urllib3 HTTPError {error}') from error
telegram.error.NetworkError: urllib3 HTTPError HTTPSConnectionPool(host='api.telegram.org', port=443): Max retries exceeded with url: /bot7327305156:AAGFKRpEVb48nB1PtSaLsPYRH8D-W9IVXiw/getUpdates (Caused by NewConnectionError('<telegram.vendor.ptb_urllib3.urllib3.connection.VerifiedHTTPSConnection object at 0x16f922440>: Failed to establish a new connection: [Errno 8] nodename nor servname provided, or not known'))
WARNING:telegram.vendor.ptb_urllib3.urllib3.connectionpool:Retrying (Retry(total=2, connect=None, read=None, redirect=None)) after connection broken by 'NewConnectionError('<telegram.vendor.ptb_urllib3.urllib3.connection.VerifiedHTTPSConnection object at 0x16f922500>: Failed to establish a new connection: [Errno 8] nodename nor servname provided, or not known')': /bot7327305156:AAGFKRpEVb48nB1PtSaLsPYRH8D-W9IVXiw/getUpdates
WARNING:telegram.vendor.ptb_urllib3.urllib3.connectionpool:Retrying (Retry(total=1, connect=None, read=None, redirect=None)) after connection broken by 'NewConnectionError('<telegram.vendor.ptb_urllib3.urllib3.connection.VerifiedHTTPSConnection object at 0x16f921ab0>: Failed to establish a new connection: [Errno 8] nodename nor servname provided, or not known')': /bot7327305156:AAGFKRpEVb48nB1PtSaLsPYRH8D-W9IVXiw/getUpdates
WARNING:telegram.vendor.ptb_urllib3.urllib3.connectionpool:Retrying (Retry(total=0, connect=None, read=None, redirect=None)) after connection broken by 'NewConnectionError('<telegram.vendor.ptb_urllib3.urllib3.connection.VerifiedHTTPSConnection object at 0x16f921c30>: Failed to establish a new connection: [Errno 8] nodename nor servname provided, or not known')': /bot7327305156:AAGFKRpEVb48nB1PtSaLsPYRH8D-W9IVXiw/getUpdates
ERROR:telegram.ext.updater:Error while getting Updates: urllib3 HTTPError HTTPSConnectionPool(host='api.telegram.org', port=443): Max retries exceeded with url: /bot7327305156:AAGFKRpEVb48nB1PtSaLsPYRH8D-W9IVXiw/getUpdates (Caused by NewConnectionError('<telegram.vendor.ptb_urllib3.urllib3.connection.VerifiedHTTPSConnection object at 0x16f920f40>: Failed to establish a new connection: [Errno 8] nodename nor servname provided, or not known'))
ERROR:__main__:Exception in update:
Traceback (most recent call last):
  File "/Users/canberkvarli/Development/peacy/venv/lib/python3.10/site-packages/telegram/vendor/ptb_urllib3/urllib3/connection.py", line 140, in _new_conn
    conn = connection.create_connection(
  File "/Users/canberkvarli/Development/peacy/venv/lib/python3.10/site-packages/telegram/vendor/ptb_urllib3/urllib3/util/connection.py", line 60, in create_connection
    for res in socket.getaddrinfo(host, port, family, socket.SOCK_STREAM):
  File "/Users/canberkvarli/.pyenv/versions/3.10.4/lib/python3.10/socket.py", line 955, in getaddrinfo
    for res in _socket.getaddrinfo(host, port, family, type, proto, flags):
socket.gaierror: [Errno 8] nodename nor servname provided, or not known

During handling of the above exception, another exception occurred:

Traceback (most recent call last):
  File "/Users/canberkvarli/Development/peacy/venv/lib/python3.10/site-packages/telegram/vendor/ptb_urllib3/urllib3/connectionpool.py", line 614, in urlopen
    httplib_response = self._make_request(conn, method, url,
  File "/Users/canberkvarli/Development/peacy/venv/lib/python3.10/site-packages/telegram/vendor/ptb_urllib3/urllib3/connectionpool.py", line 360, in _make_request
    self._validate_conn(conn)
  File "/Users/canberkvarli/Development/peacy/venv/lib/python3.10/site-packages/telegram/vendor/ptb_urllib3/urllib3/connectionpool.py", line 857, in _validate_conn
    super(HTTPSConnectionPool, self)._validate_conn(conn)
  File "/Users/canberkvarli/Development/peacy/venv/lib/python3.10/site-packages/telegram/vendor/ptb_urllib3/urllib3/connectionpool.py", line 289, in _validate_conn
    conn.connect()
  File "/Users/canberkvarli/Development/peacy/venv/lib/python3.10/site-packages/telegram/vendor/ptb_urllib3/urllib3/connection.py", line 284, in connect
    conn = self._new_conn()
  File "/Users/canberkvarli/Development/peacy/venv/lib/python3.10/site-packages/telegram/vendor/ptb_urllib3/urllib3/connection.py", line 149, in _new_conn
    raise NewConnectionError(
telegram.vendor.ptb_urllib3.urllib3.exceptions.NewConnectionError: <telegram.vendor.ptb_urllib3.urllib3.connection.VerifiedHTTPSConnection object at 0x16f920f40>: Failed to establish a new connection: [Errno 8] nodename nor servname provided, or not known

During handling of the above exception, another exception occurred:

Traceback (most recent call last):
  File "/Users/canberkvarli/Development/peacy/venv/lib/python3.10/site-packages/telegram/utils/request.py", line 259, in _request_wrapper
    resp = self._con_pool.request(*args, **kwargs)
  File "/Users/canberkvarli/Development/peacy/venv/lib/python3.10/site-packages/telegram/vendor/ptb_urllib3/urllib3/request.py", line 68, in request
    return self.request_encode_body(method, url, fields=fields,
  File "/Users/canberkvarli/Development/peacy/venv/lib/python3.10/site-packages/telegram/vendor/ptb_urllib3/urllib3/request.py", line 148, in request_encode_body
    return self.urlopen(method, url, **extra_kw)
  File "/Users/canberkvarli/Development/peacy/venv/lib/python3.10/site-packages/telegram/vendor/ptb_urllib3/urllib3/poolmanager.py", line 244, in urlopen
    response = conn.urlopen(method, u.request_uri, **kw)
  File "/Users/canberkvarli/Development/peacy/venv/lib/python3.10/site-packages/telegram/vendor/ptb_urllib3/urllib3/connectionpool.py", line 691, in urlopen
    return self.urlopen(method, url, body, headers, retries,
  File "/Users/canberkvarli/Development/peacy/venv/lib/python3.10/site-packages/telegram/vendor/ptb_urllib3/urllib3/connectionpool.py", line 691, in urlopen
    return self.urlopen(method, url, body, headers, retries,
  File "/Users/canberkvarli/Development/peacy/venv/lib/python3.10/site-packages/telegram/vendor/ptb_urllib3/urllib3/connectionpool.py", line 691, in urlopen
    return self.urlopen(method, url, body, headers, retries,
  File "/Users/canberkvarli/Development/peacy/venv/lib/python3.10/site-packages/telegram/vendor/ptb_urllib3/urllib3/connectionpool.py", line 665, in urlopen
    retries = retries.increment(method, url, error=e, _pool=self,
  File "/Users/canberkvarli/Development/peacy/venv/lib/python3.10/site-packages/telegram/vendor/ptb_urllib3/urllib3/util/retry.py", line 376, in increment
    raise MaxRetryError(_pool, url, error or ResponseError(cause))
telegram.vendor.ptb_urllib3.urllib3.exceptions.MaxRetryError: HTTPSConnectionPool(host='api.telegram.org', port=443): Max retries exceeded with url: /bot7327305156:AAGFKRpEVb48nB1PtSaLsPYRH8D-W9IVXiw/getUpdates (Caused by NewConnectionError('<telegram.vendor.ptb_urllib3.urllib3.connection.VerifiedHTTPSConnection object at 0x16f920f40>: Failed to establish a new connection: [Errno 8] nodename nor servname provided, or not known'))

The above exception was the direct cause of the following exception:

Traceback (most recent call last):
  File "/Users/canberkvarli/Development/peacy/venv/lib/python3.10/site-packages/telegram/ext/updater.py", line 651, in _network_loop_retry
    if not action_cb():
  File "/Users/canberkvarli/Development/peacy/venv/lib/python3.10/site-packages/telegram/ext/updater.py", line 602, in polling_action_cb
    updates = self.bot.get_updates(
  File "/Users/canberkvarli/Development/peacy/venv/lib/python3.10/site-packages/telegram/ext/extbot.py", line 228, in get_updates
    updates = super().get_updates(
  File "/Users/canberkvarli/Development/peacy/venv/lib/python3.10/site-packages/telegram/bot.py", line 134, in decorator
    result = func(*args, **kwargs)
  File "/Users/canberkvarli/Development/peacy/venv/lib/python3.10/site-packages/telegram/bot.py", line 3140, in get_updates
    self._post(
  File "/Users/canberkvarli/Development/peacy/venv/lib/python3.10/site-packages/telegram/bot.py", line 299, in _post
    return self.request.post(
  File "/Users/canberkvarli/Development/peacy/venv/lib/python3.10/site-packages/telegram/utils/request.py", line 361, in post
    result = self._request_wrapper(
  File "/Users/canberkvarli/Development/peacy/venv/lib/python3.10/site-packages/telegram/utils/request.py", line 265, in _request_wrapper
    raise NetworkError(f'urllib3 HTTPError {error}') from error
telegram.error.NetworkError: urllib3 HTTPError HTTPSConnectionPool(host='api.telegram.org', port=443): Max retries exceeded with url: /bot7327305156:AAGFKRpEVb48nB1PtSaLsPYRH8D-W9IVXiw/getUpdates (Caused by NewConnectionError('<telegram.vendor.ptb_urllib3.urllib3.connection.VerifiedHTTPSConnection object at 0x16f920f40>: Failed to establish a new connection: [Errno 8] nodename nor servname provided, or not known'))
WARNING:telegram.vendor.ptb_urllib3.urllib3.connectionpool:Retrying (Retry(total=2, connect=None, read=None, redirect=None)) after connection broken by 'NewConnectionError('<telegram.vendor.ptb_urllib3.urllib3.connection.VerifiedHTTPSConnection object at 0x16f920c70>: Failed to establish a new connection: [Errno 8] nodename nor servname provided, or not known')': /bot7327305156:AAGFKRpEVb48nB1PtSaLsPYRH8D-W9IVXiw/getUpdates
WARNING:telegram.vendor.ptb_urllib3.urllib3.connectionpool:Retrying (Retry(total=1, connect=None, read=None, redirect=None)) after connection broken by 'NewConnectionError('<telegram.vendor.ptb_urllib3.urllib3.connection.VerifiedHTTPSConnection object at 0x16f9201c0>: Failed to establish a new connection: [Errno 8] nodename nor servname provided, or not known')': /bot7327305156:AAGFKRpEVb48nB1PtSaLsPYRH8D-W9IVXiw/getUpdates
WARNING:telegram.vendor.ptb_urllib3.urllib3.connectionpool:Retrying (Retry(total=0, connect=None, read=None, redirect=None)) after connection broken by 'NewConnectionError('<telegram.vendor.ptb_urllib3.urllib3.connection.VerifiedHTTPSConnection object at 0x16f922bc0>: Failed to establish a new connection: [Errno 8] nodename nor servname provided, or not known')': /bot7327305156:AAGFKRpEVb48nB1PtSaLsPYRH8D-W9IVXiw/getUpdates
ERROR:telegram.ext.updater:Error while getting Updates: urllib3 HTTPError HTTPSConnectionPool(host='api.telegram.org', port=443): Max retries exceeded with url: /bot7327305156:AAGFKRpEVb48nB1PtSaLsPYRH8D-W9IVXiw/getUpdates (Caused by NewConnectionError('<telegram.vendor.ptb_urllib3.urllib3.connection.VerifiedHTTPSConnection object at 0x16f922b30>: Failed to establish a new connection: [Errno 8] nodename nor servname provided, or not known'))
ERROR:__main__:Exception in update:
Traceback (most recent call last):
  File "/Users/canberkvarli/Development/peacy/venv/lib/python3.10/site-packages/telegram/vendor/ptb_urllib3/urllib3/connection.py", line 140, in _new_conn
    conn = connection.create_connection(
  File "/Users/canberkvarli/Development/peacy/venv/lib/python3.10/site-packages/telegram/vendor/ptb_urllib3/urllib3/util/connection.py", line 60, in create_connection
    for res in socket.getaddrinfo(host, port, family, socket.SOCK_STREAM):
  File "/Users/canberkvarli/.pyenv/versions/3.10.4/lib/python3.10/socket.py", line 955, in getaddrinfo
    for res in _socket.getaddrinfo(host, port, family, type, proto, flags):
socket.gaierror: [Errno 8] nodename nor servname provided, or not known

During handling of the above exception, another exception occurred:

Traceback (most recent call last):
  File "/Users/canberkvarli/Development/peacy/venv/lib/python3.10/site-packages/telegram/vendor/ptb_urllib3/urllib3/connectionpool.py", line 614, in urlopen
    httplib_response = self._make_request(conn, method, url,
  File "/Users/canberkvarli/Development/peacy/venv/lib/python3.10/site-packages/telegram/vendor/ptb_urllib3/urllib3/connectionpool.py", line 360, in _make_request
    self._validate_conn(conn)
  File "/Users/canberkvarli/Development/peacy/venv/lib/python3.10/site-packages/telegram/vendor/ptb_urllib3/urllib3/connectionpool.py", line 857, in _validate_conn
    super(HTTPSConnectionPool, self)._validate_conn(conn)
  File "/Users/canberkvarli/Development/peacy/venv/lib/python3.10/site-packages/telegram/vendor/ptb_urllib3/urllib3/connectionpool.py", line 289, in _validate_conn
    conn.connect()
  File "/Users/canberkvarli/Development/peacy/venv/lib/python3.10/site-packages/telegram/vendor/ptb_urllib3/urllib3/connection.py", line 284, in connect
    conn = self._new_conn()
  File "/Users/canberkvarli/Development/peacy/venv/lib/python3.10/site-packages/telegram/vendor/ptb_urllib3/urllib3/connection.py", line 149, in _new_conn
    raise NewConnectionError(
telegram.vendor.ptb_urllib3.urllib3.exceptions.NewConnectionError: <telegram.vendor.ptb_urllib3.urllib3.connection.VerifiedHTTPSConnection object at 0x16f922b30>: Failed to establish a new connection: [Errno 8] nodename nor servname provided, or not known

During handling of the above exception, another exception occurred:

Traceback (most recent call last):
  File "/Users/canberkvarli/Development/peacy/venv/lib/python3.10/site-packages/telegram/utils/request.py", line 259, in _request_wrapper
    resp = self._con_pool.request(*args, **kwargs)
  File "/Users/canberkvarli/Development/peacy/venv/lib/python3.10/site-packages/telegram/vendor/ptb_urllib3/urllib3/request.py", line 68, in request
    return self.request_encode_body(method, url, fields=fields,
  File "/Users/canberkvarli/Development/peacy/venv/lib/python3.10/site-packages/telegram/vendor/ptb_urllib3/urllib3/request.py", line 148, in request_encode_body
    return self.urlopen(method, url, **extra_kw)
  File "/Users/canberkvarli/Development/peacy/venv/lib/python3.10/site-packages/telegram/vendor/ptb_urllib3/urllib3/poolmanager.py", line 244, in urlopen
    response = conn.urlopen(method, u.request_uri, **kw)
  File "/Users/canberkvarli/Development/peacy/venv/lib/python3.10/site-packages/telegram/vendor/ptb_urllib3/urllib3/connectionpool.py", line 691, in urlopen
    return self.urlopen(method, url, body, headers, retries,
  File "/Users/canberkvarli/Development/peacy/venv/lib/python3.10/site-packages/telegram/vendor/ptb_urllib3/urllib3/connectionpool.py", line 691, in urlopen
    return self.urlopen(method, url, body, headers, retries,
  File "/Users/canberkvarli/Development/peacy/venv/lib/python3.10/site-packages/telegram/vendor/ptb_urllib3/urllib3/connectionpool.py", line 691, in urlopen
    return self.urlopen(method, url, body, headers, retries,
  File "/Users/canberkvarli/Development/peacy/venv/lib/python3.10/site-packages/telegram/vendor/ptb_urllib3/urllib3/connectionpool.py", line 665, in urlopen
    retries = retries.increment(method, url, error=e, _pool=self,
  File "/Users/canberkvarli/Development/peacy/venv/lib/python3.10/site-packages/telegram/vendor/ptb_urllib3/urllib3/util/retry.py", line 376, in increment
    raise MaxRetryError(_pool, url, error or ResponseError(cause))
telegram.vendor.ptb_urllib3.urllib3.exceptions.MaxRetryError: HTTPSConnectionPool(host='api.telegram.org', port=443): Max retries exceeded with url: /bot7327305156:AAGFKRpEVb48nB1PtSaLsPYRH8D-W9IVXiw/getUpdates (Caused by NewConnectionError('<telegram.vendor.ptb_urllib3.urllib3.connection.VerifiedHTTPSConnection object at 0x16f922b30>: Failed to establish a new connection: [Errno 8] nodename nor servname provided, or not known'))

The above exception was the direct cause of the following exception:

Traceback (most recent call last):
  File "/Users/canberkvarli/Development/peacy/venv/lib/python3.10/site-packages/telegram/ext/updater.py", line 651, in _network_loop_retry
    if not action_cb():
  File "/Users/canberkvarli/Development/peacy/venv/lib/python3.10/site-packages/telegram/ext/updater.py", line 602, in polling_action_cb
    updates = self.bot.get_updates(
  File "/Users/canberkvarli/Development/peacy/venv/lib/python3.10/site-packages/telegram/ext/extbot.py", line 228, in get_updates
    updates = super().get_updates(
  File "/Users/canberkvarli/Development/peacy/venv/lib/python3.10/site-packages/telegram/bot.py", line 134, in decorator
    result = func(*args, **kwargs)
  File "/Users/canberkvarli/Development/peacy/venv/lib/python3.10/site-packages/telegram/bot.py", line 3140, in get_updates
    self._post(
  File "/Users/canberkvarli/Development/peacy/venv/lib/python3.10/site-packages/telegram/bot.py", line 299, in _post
    return self.request.post(
  File "/Users/canberkvarli/Development/peacy/venv/lib/python3.10/site-packages/telegram/utils/request.py", line 361, in post
    result = self._request_wrapper(
  File "/Users/canberkvarli/Development/peacy/venv/lib/python3.10/site-packages/telegram/utils/request.py", line 265, in _request_wrapper
    raise NetworkError(f'urllib3 HTTPError {error}') from error
telegram.error.NetworkError: urllib3 HTTPError HTTPSConnectionPool(host='api.telegram.org', port=443): Max retries exceeded with url: /bot7327305156:AAGFKRpEVb48nB1PtSaLsPYRH8D-W9IVXiw/getUpdates (Caused by NewConnectionError('<telegram.vendor.ptb_urllib3.urllib3.connection.VerifiedHTTPSConnection object at 0x16f922b30>: Failed to establish a new connection: [Errno 8] nodename nor servname provided, or not known'))
WARNING:telegram.vendor.ptb_urllib3.urllib3.connectionpool:Retrying (Retry(total=2, connect=None, read=None, redirect=None)) after connection broken by 'NewConnectionError('<telegram.vendor.ptb_urllib3.urllib3.connection.VerifiedHTTPSConnection object at 0x16f920100>: Failed to establish a new connection: [Errno 8] nodename nor servname provided, or not known')': /bot7327305156:AAGFKRpEVb48nB1PtSaLsPYRH8D-W9IVXiw/getUpdates
WARNING:telegram.vendor.ptb_urllib3.urllib3.connectionpool:Retrying (Retry(total=1, connect=None, read=None, redirect=None)) after connection broken by 'NewConnectionError('<telegram.vendor.ptb_urllib3.urllib3.connection.VerifiedHTTPSConnection object at 0x16f922b60>: Failed to establish a new connection: [Errno 8] nodename nor servname provided, or not known')': /bot7327305156:AAGFKRpEVb48nB1PtSaLsPYRH8D-W9IVXiw/getUpdates
WARNING:telegram.vendor.ptb_urllib3.urllib3.connectionpool:Retrying (Retry(total=0, connect=None, read=None, redirect=None)) after connection broken by 'NewConnectionError('<telegram.vendor.ptb_urllib3.urllib3.connection.VerifiedHTTPSConnection object at 0x16f9231c0>: Failed to establish a new connection: [Errno 8] nodename nor servname provided, or not known')': /bot7327305156:AAGFKRpEVb48nB1PtSaLsPYRH8D-W9IVXiw/getUpdates
ERROR:telegram.ext.updater:Error while getting Updates: urllib3 HTTPError HTTPSConnectionPool(host='api.telegram.org', port=443): Max retries exceeded with url: /bot7327305156:AAGFKRpEVb48nB1PtSaLsPYRH8D-W9IVXiw/getUpdates (Caused by NewConnectionError('<telegram.vendor.ptb_urllib3.urllib3.connection.VerifiedHTTPSConnection object at 0x16f923310>: Failed to establish a new connection: [Errno 8] nodename nor servname provided, or not known'))
ERROR:__main__:Exception in update:
Traceback (most recent call last):
  File "/Users/canberkvarli/Development/peacy/venv/lib/python3.10/site-packages/telegram/vendor/ptb_urllib3/urllib3/connection.py", line 140, in _new_conn
    conn = connection.create_connection(
  File "/Users/canberkvarli/Development/peacy/venv/lib/python3.10/site-packages/telegram/vendor/ptb_urllib3/urllib3/util/connection.py", line 60, in create_connection
    for res in socket.getaddrinfo(host, port, family, socket.SOCK_STREAM):
  File "/Users/canberkvarli/.pyenv/versions/3.10.4/lib/python3.10/socket.py", line 955, in getaddrinfo
    for res in _socket.getaddrinfo(host, port, family, type, proto, flags):
socket.gaierror: [Errno 8] nodename nor servname provided, or not known

During handling of the above exception, another exception occurred:

Traceback (most recent call last):
  File "/Users/canberkvarli/Development/peacy/venv/lib/python3.10/site-packages/telegram/vendor/ptb_urllib3/urllib3/connectionpool.py", line 614, in urlopen
    httplib_response = self._make_request(conn, method, url,
  File "/Users/canberkvarli/Development/peacy/venv/lib/python3.10/site-packages/telegram/vendor/ptb_urllib3/urllib3/connectionpool.py", line 360, in _make_request
    self._validate_conn(conn)
  File "/Users/canberkvarli/Development/peacy/venv/lib/python3.10/site-packages/telegram/vendor/ptb_urllib3/urllib3/connectionpool.py", line 857, in _validate_conn
    super(HTTPSConnectionPool, self)._validate_conn(conn)
  File "/Users/canberkvarli/Development/peacy/venv/lib/python3.10/site-packages/telegram/vendor/ptb_urllib3/urllib3/connectionpool.py", line 289, in _validate_conn
    conn.connect()
  File "/Users/canberkvarli/Development/peacy/venv/lib/python3.10/site-packages/telegram/vendor/ptb_urllib3/urllib3/connection.py", line 284, in connect
    conn = self._new_conn()
  File "/Users/canberkvarli/Development/peacy/venv/lib/python3.10/site-packages/telegram/vendor/ptb_urllib3/urllib3/connection.py", line 149, in _new_conn
    raise NewConnectionError(
telegram.vendor.ptb_urllib3.urllib3.exceptions.NewConnectionError: <telegram.vendor.ptb_urllib3.urllib3.connection.VerifiedHTTPSConnection object at 0x16f923310>: Failed to establish a new connection: [Errno 8] nodename nor servname provided, or not known

During handling of the above exception, another exception occurred:

Traceback (most recent call last):
  File "/Users/canberkvarli/Development/peacy/venv/lib/python3.10/site-packages/telegram/utils/request.py", line 259, in _request_wrapper
    resp = self._con_pool.request(*args, **kwargs)
  File "/Users/canberkvarli/Development/peacy/venv/lib/python3.10/site-packages/telegram/vendor/ptb_urllib3/urllib3/request.py", line 68, in request
    return self.request_encode_body(method, url, fields=fields,
  File "/Users/canberkvarli/Development/peacy/venv/lib/python3.10/site-packages/telegram/vendor/ptb_urllib3/urllib3/request.py", line 148, in request_encode_body
    return self.urlopen(method, url, **extra_kw)
  File "/Users/canberkvarli/Development/peacy/venv/lib/python3.10/site-packages/telegram/vendor/ptb_urllib3/urllib3/poolmanager.py", line 244, in urlopen
    response = conn.urlopen(method, u.request_uri, **kw)
  File "/Users/canberkvarli/Development/peacy/venv/lib/python3.10/site-packages/telegram/vendor/ptb_urllib3/urllib3/connectionpool.py", line 691, in urlopen
    return self.urlopen(method, url, body, headers, retries,
  File "/Users/canberkvarli/Development/peacy/venv/lib/python3.10/site-packages/telegram/vendor/ptb_urllib3/urllib3/connectionpool.py", line 691, in urlopen
    return self.urlopen(method, url, body, headers, retries,
  File "/Users/canberkvarli/Development/peacy/venv/lib/python3.10/site-packages/telegram/vendor/ptb_urllib3/urllib3/connectionpool.py", line 691, in urlopen
    return self.urlopen(method, url, body, headers, retries,
  File "/Users/canberkvarli/Development/peacy/venv/lib/python3.10/site-packages/telegram/vendor/ptb_urllib3/urllib3/connectionpool.py", line 665, in urlopen
    retries = retries.increment(method, url, error=e, _pool=self,
  File "/Users/canberkvarli/Development/peacy/venv/lib/python3.10/site-packages/telegram/vendor/ptb_urllib3/urllib3/util/retry.py", line 376, in increment
    raise MaxRetryError(_pool, url, error or ResponseError(cause))
telegram.vendor.ptb_urllib3.urllib3.exceptions.MaxRetryError: HTTPSConnectionPool(host='api.telegram.org', port=443): Max retries exceeded with url: /bot7327305156:AAGFKRpEVb48nB1PtSaLsPYRH8D-W9IVXiw/getUpdates (Caused by NewConnectionError('<telegram.vendor.ptb_urllib3.urllib3.connection.VerifiedHTTPSConnection object at 0x16f923310>: Failed to establish a new connection: [Errno 8] nodename nor servname provided, or not known'))

The above exception was the direct cause of the following exception:

Traceback (most recent call last):
  File "/Users/canberkvarli/Development/peacy/venv/lib/python3.10/site-packages/telegram/ext/updater.py", line 651, in _network_loop_retry
    if not action_cb():
  File "/Users/canberkvarli/Development/peacy/venv/lib/python3.10/site-packages/telegram/ext/updater.py", line 602, in polling_action_cb
    updates = self.bot.get_updates(
  File "/Users/canberkvarli/Development/peacy/venv/lib/python3.10/site-packages/telegram/ext/extbot.py", line 228, in get_updates
    updates = super().get_updates(
  File "/Users/canberkvarli/Development/peacy/venv/lib/python3.10/site-packages/telegram/bot.py", line 134, in decorator
    result = func(*args, **kwargs)
  File "/Users/canberkvarli/Development/peacy/venv/lib/python3.10/site-packages/telegram/bot.py", line 3140, in get_updates
    self._post(
  File "/Users/canberkvarli/Development/peacy/venv/lib/python3.10/site-packages/telegram/bot.py", line 299, in _post
    return self.request.post(
  File "/Users/canberkvarli/Development/peacy/venv/lib/python3.10/site-packages/telegram/utils/request.py", line 361, in post
    result = self._request_wrapper(
  File "/Users/canberkvarli/Development/peacy/venv/lib/python3.10/site-packages/telegram/utils/request.py", line 265, in _request_wrapper
    raise NetworkError(f'urllib3 HTTPError {error}') from error
telegram.error.NetworkError: urllib3 HTTPError HTTPSConnectionPool(host='api.telegram.org', port=443): Max retries exceeded with url: /bot7327305156:AAGFKRpEVb48nB1PtSaLsPYRH8D-W9IVXiw/getUpdates (Caused by NewConnectionError('<telegram.vendor.ptb_urllib3.urllib3.connection.VerifiedHTTPSConnection object at 0x16f923310>: Failed to establish a new connection: [Errno 8] nodename nor servname provided, or not known'))
WARNING:apscheduler.executors.default:Run time of job "summarize_conversations (trigger: interval[0:30:00], next run at: 2025-03-16 22:48:03 UTC)" was missed by 0:11:35.241692
DEBUG:Chroma:time to pre process our knn query: 1.9073486328125e-06
ERROR:__main__:Exception in handle_message:
Traceback (most recent call last):
  File "/Users/canberkvarli/Development/peacy/bot.py", line 66, in handle_message
    memory_context = retrieve_memory(user_message, n_results=3)
  File "/Users/canberkvarli/Development/peacy/memory_manager.py", line 46, in retrieve_memory
    results = collection.query(
  File "/Users/canberkvarli/Development/peacy/venv/lib/python3.10/site-packages/chromadb/api/models/Collection.py", line 165, in query
    return self._client._query(
  File "/Users/canberkvarli/Development/peacy/venv/lib/python3.10/site-packages/chromadb/api/local.py", line 192, in _query
    uuids, distances = self._db.get_nearest_neighbors(
  File "/Users/canberkvarli/Development/peacy/venv/lib/python3.10/site-packages/chromadb/db/clickhouse.py", line 393, in get_nearest_neighbors
    uuids, distances = self._idx.get_nearest_neighbors(
  File "/Users/canberkvarli/Development/peacy/venv/lib/python3.10/site-packages/chromadb/db/index/hnswlib.py", line 182, in get_nearest_neighbors
    database_ids, distances = self._index.knn_query(query, k=k, filter=filter_function)
RuntimeError: Cannot return the results in a contiguous 2D array. Probably ef or M is too small
WARNING:telegram.ext.updater:Exiting immediately!
DEBUG:Chroma:Logger created
DEBUG:Chroma:Index not found
DEBUG:Chroma:Index saved to {self._save_folder}/index.bin
DEBUG:Chroma:Index saved to {self._save_folder}/index.bin
DEBUG:Chroma:Logger created
DEBUG:Chroma:time to pre process our knn query: 4.0531158447265625e-06
DEBUG:Chroma:time to run knn query: 0.0002980232238769531
DEBUG:Chroma:Logger created
DEBUG:Chroma:time to pre process our knn query: 4.0531158447265625e-06
DEBUG:Chroma:time to run knn query: 0.0003058910369873047
DEBUG:Chroma:Logger created
DEBUG:Chroma:time to pre process our knn query: 4.0531158447265625e-06
DEBUG:Chroma:time to run knn query: 0.00027298927307128906
DEBUG:Chroma:Logger created
DEBUG:Chroma:time to pre process our knn query: 2.86102294921875e-06
DEBUG:Chroma:time to run knn query: 0.0002560615539550781
DEBUG:Chroma:Logger created
DEBUG:Chroma:time to pre process our knn query: 1.0013580322265625e-05
DEBUG:Chroma:time to run knn query: 0.0006792545318603516
DEBUG:Chroma:Logger created
DEBUG:Chroma:time to pre process our knn query: 4.0531158447265625e-06
DEBUG:Chroma:time to run knn query: 0.00031495094299316406
DEBUG:Chroma:Logger created
DEBUG:Chroma:time to pre process our knn query: 4.0531158447265625e-06
DEBUG:Chroma:time to run knn query: 0.0002498626708984375
DEBUG:Chroma:Logger created
DEBUG:Chroma:time to pre process our knn query: 5.9604644775390625e-06
DEBUG:Chroma:time to run knn query: 0.0003418922424316406
DEBUG:Chroma:Logger created
DEBUG:Chroma:time to pre process our knn query: 4.0531158447265625e-06
DEBUG:Chroma:time to run knn query: 0.00034880638122558594
DEBUG:Chroma:Logger created
DEBUG:Chroma:time to pre process our knn query: 4.76837158203125e-06
DEBUG:Chroma:time to run knn query: 0.00035309791564941406
DEBUG:Chroma:Logger created
DEBUG:Chroma:time to pre process our knn query: 4.0531158447265625e-06
DEBUG:Chroma:time to run knn query: 0.00026607513427734375
DEBUG:Chroma:time to pre process our knn query: 1.6689300537109375e-06
DEBUG:Chroma:time to run knn query: 6.818771362304688e-05
DEBUG:Chroma:Index saved to {self._save_folder}/index.bin
DEBUG:Chroma:Index saved to {self._save_folder}/index.bin
DEBUG:Chroma:time to pre process our knn query: 9.5367431640625e-07
DEBUG:Chroma:time to run knn query: 2.09808349609375e-05
DEBUG:Chroma:Index saved to {self._save_folder}/index.bin
DEBUG:Chroma:Index saved to {self._save_folder}/index.bin
DEBUG:Chroma:time to pre process our knn query: 4.76837158203125e-06
DEBUG:Chroma:time to run knn query: 8.797645568847656e-05
DEBUG:Chroma:Index saved to {self._save_folder}/index.bin
DEBUG:Chroma:Index saved to {self._save_folder}/index.bin
DEBUG:Chroma:time to pre process our knn query: 5.9604644775390625e-06
DEBUG:Chroma:time to run knn query: 6.67572021484375e-05
DEBUG:Chroma:Index saved to {self._save_folder}/index.bin
DEBUG:Chroma:Index saved to {self._save_folder}/index.bin
DEBUG:Chroma:Logger created
DEBUG:Chroma:time to pre process our knn query: 5.0067901611328125e-06
DEBUG:Chroma:time to run knn query: 0.0003180503845214844
DEBUG:Chroma:time to pre process our knn query: 4.0531158447265625e-06
DEBUG:Chroma:time to run knn query: 0.0007390975952148438
DEBUG:Chroma:Index saved to {self._save_folder}/index.bin
DEBUG:Chroma:Index saved to {self._save_folder}/index.bin
DEBUG:Chroma:time to pre process our knn query: 2.1457672119140625e-06
DEBUG:Chroma:time to run knn query: 7.009506225585938e-05
DEBUG:Chroma:Index saved to {self._save_folder}/index.bin
DEBUG:Chroma:Index saved to {self._save_folder}/index.bin
DEBUG:Chroma:time to pre process our knn query: 7.867813110351562e-06
DEBUG:Chroma:time to run knn query: 0.00012183189392089844
DEBUG:Chroma:Index saved to {self._save_folder}/index.bin
DEBUG:Chroma:Index saved to {self._save_folder}/index.bin
DEBUG:Chroma:time to pre process our knn query: 6.9141387939453125e-06
DEBUG:Chroma:time to run knn query: 8.225440979003906e-05
DEBUG:Chroma:Index saved to {self._save_folder}/index.bin
DEBUG:Chroma:Index saved to {self._save_folder}/index.bin
DEBUG:Chroma:time to pre process our knn query: 7.152557373046875e-06
DEBUG:Chroma:time to run knn query: 6.508827209472656e-05
DEBUG:Chroma:Index saved to {self._save_folder}/index.bin
DEBUG:Chroma:Index saved to {self._save_folder}/index.bin
DEBUG:Chroma:Logger created
DEBUG:Chroma:time to pre process our knn query: 3.2901763916015625e-05
DEBUG:Chroma:time to run knn query: 0.00028395652770996094
DEBUG:Chroma:time to pre process our knn query: 4.76837158203125e-06
DEBUG:Chroma:time to run knn query: 8.20159912109375e-05
DEBUG:Chroma:Index saved to {self._save_folder}/index.bin
DEBUG:Chroma:Index saved to {self._save_folder}/index.bin
DEBUG:Chroma:time to pre process our knn query: 1.9073486328125e-06
DEBUG:Chroma:time to run knn query: 4.1961669921875e-05
DEBUG:Chroma:Index saved to {self._save_folder}/index.bin
DEBUG:Chroma:Index saved to {self._save_folder}/index.bin
DEBUG:Chroma:time to pre process our knn query: 9.5367431640625e-07
DEBUG:Chroma:time to run knn query: 5.078315734863281e-05
DEBUG:Chroma:Index saved to {self._save_folder}/index.bin
DEBUG:Chroma:Index saved to {self._save_folder}/index.bin
DEBUG:Chroma:time to pre process our knn query: 1.6689300537109375e-06
DEBUG:Chroma:time to run knn query: 7.581710815429688e-05
DEBUG:Chroma:Index saved to {self._save_folder}/index.bin
DEBUG:Chroma:Index saved to {self._save_folder}/index.bin
DEBUG:Chroma:Logger created
DEBUG:Chroma:time to pre process our knn query: 6.198883056640625e-06
DEBUG:Chroma:time to run knn query: 0.0003151893615722656
DEBUG:Chroma:time to pre process our knn query: 7.152557373046875e-06
DEBUG:Chroma:time to run knn query: 0.00012183189392089844
DEBUG:Chroma:Index saved to {self._save_folder}/index.bin
DEBUG:Chroma:Index saved to {self._save_folder}/index.bin
DEBUG:Chroma:Logger created
DEBUG:Chroma:time to pre process our knn query: 3.814697265625e-06
DEBUG:Chroma:time to run knn query: 0.0002639293670654297
